{
 "cells": [
  {
   "cell_type": "code",
   "execution_count": 2,
   "id": "b9c21d96",
   "metadata": {},
   "outputs": [],
   "source": [
    "from keras.datasets import fashion_mnist\n",
    "(x_train, y_train), (x_test, y_test) = fashion_mnist.load_data()\n",
    "\n",
    "# reshape dataset to have a single channel\n",
    "x_train = x_train.reshape((x_train.shape[0], 28, 28, 1))\n",
    "x_test = x_test.reshape((x_test.shape[0], 28, 28, 1))"
   ]
  },
  {
   "cell_type": "code",
   "execution_count": 3,
   "id": "9d8821bd",
   "metadata": {},
   "outputs": [],
   "source": [
    "#packages\n",
    "\n",
    "import numpy as np\n",
    "import tensorflow as tf\n",
    "from keras.datasets import cifar10\n",
    "from keras.models import Sequential\n",
    "from keras.layers import Dense\n",
    "from keras.layers import Dropout\n",
    "from keras.layers import Flatten\n",
    "from keras.constraints import maxnorm\n",
    "from keras.optimizers import SGD\n",
    "from keras.layers.convolutional import Conv2D\n",
    "from keras.layers.convolutional import MaxPooling2D\n",
    "from keras.utils import np_utils"
   ]
  },
  {
   "cell_type": "code",
   "execution_count": 4,
   "id": "1da85590",
   "metadata": {},
   "outputs": [],
   "source": [
    "# normalize inputs \n",
    "x_train = x_train.astype('float32')\n",
    "x_test = x_test.astype('float32')\n",
    "x_train = x_train / 255.0 \n",
    "x_test = x_test / 255.0"
   ]
  },
  {
   "cell_type": "code",
   "execution_count": 5,
   "id": "fe85b700",
   "metadata": {},
   "outputs": [],
   "source": [
    "# Encode outputs\n",
    "y_train = np_utils.to_categorical(y_train,10) \n",
    "y_test = np_utils.to_categorical(y_test,10)\n",
    "num_classes = y_train.shape[1]"
   ]
  },
  {
   "cell_type": "code",
   "execution_count": null,
   "id": "4af8c234",
   "metadata": {},
   "outputs": [
    {
     "name": "stderr",
     "output_type": "stream",
     "text": [
      "ERROR:root:Internal Python error in the inspect module.\n",
      "Below is the traceback from this internal error.\n",
      "\n",
      "ERROR:root:Internal Python error in the inspect module.\n",
      "Below is the traceback from this internal error.\n",
      "\n",
      "ERROR:root:Internal Python error in the inspect module.\n",
      "Below is the traceback from this internal error.\n",
      "\n"
     ]
    },
    {
     "name": "stdout",
     "output_type": "stream",
     "text": [
      "Traceback (most recent call last):\n",
      "  File \"/Users/taylorschneider/opt/anaconda3/envs/py37tf/lib/python3.7/site-packages/IPython/core/interactiveshell.py\", line 3457, in run_code\n",
      "    exec(code_obj, self.user_global_ns, self.user_ns)\n",
      "  File \"/var/folders/mx/lrbgms150gdbdt3pfhw4t3m00000gn/T/ipykernel_1737/267833325.py\", line 5, in <module>\n",
      "    model.add(Conv2D(28, (3, 3), input_shape=(28, 28), activation='relu', padding='same'))\n",
      "  File \"/Users/taylorschneider/opt/anaconda3/envs/py37tf/lib/python3.7/site-packages/keras/engine/sequential.py\", line 166, in add\n",
      "    layer(x)\n",
      "  File \"/Users/taylorschneider/opt/anaconda3/envs/py37tf/lib/python3.7/site-packages/keras/engine/base_layer.py\", line 446, in __call__\n",
      "    self.assert_input_compatibility(inputs)\n",
      "  File \"/Users/taylorschneider/opt/anaconda3/envs/py37tf/lib/python3.7/site-packages/keras/engine/base_layer.py\", line 342, in assert_input_compatibility\n",
      "    str(K.ndim(x)))\n",
      "ValueError: Input 0 is incompatible with layer conv2d_1: expected ndim=4, found ndim=3\n",
      "\n",
      "During handling of the above exception, another exception occurred:\n",
      "\n",
      "Traceback (most recent call last):\n",
      "  File \"/Users/taylorschneider/opt/anaconda3/envs/py37tf/lib/python3.7/site-packages/IPython/core/interactiveshell.py\", line 2077, in showtraceback\n",
      "    stb = value._render_traceback_()\n",
      "AttributeError: 'ValueError' object has no attribute '_render_traceback_'\n",
      "\n",
      "During handling of the above exception, another exception occurred:\n",
      "\n",
      "Traceback (most recent call last):\n",
      "  File \"/Users/taylorschneider/opt/anaconda3/envs/py37tf/lib/python3.7/site-packages/IPython/core/ultratb.py\", line 1101, in get_records\n",
      "    return _fixed_getinnerframes(etb, number_of_lines_of_context, tb_offset)\n",
      "  File \"/Users/taylorschneider/opt/anaconda3/envs/py37tf/lib/python3.7/site-packages/IPython/core/ultratb.py\", line 248, in wrapped\n",
      "    return f(*args, **kwargs)\n",
      "  File \"/Users/taylorschneider/opt/anaconda3/envs/py37tf/lib/python3.7/site-packages/IPython/core/ultratb.py\", line 281, in _fixed_getinnerframes\n",
      "    records = fix_frame_records_filenames(inspect.getinnerframes(etb, context))\n",
      "  File \"/Users/taylorschneider/opt/anaconda3/envs/py37tf/lib/python3.7/inspect.py\", line 1502, in getinnerframes\n",
      "    frameinfo = (tb.tb_frame,) + getframeinfo(tb, context)\n",
      "  File \"/Users/taylorschneider/opt/anaconda3/envs/py37tf/lib/python3.7/inspect.py\", line 1460, in getframeinfo\n",
      "    filename = getsourcefile(frame) or getfile(frame)\n",
      "  File \"/Users/taylorschneider/opt/anaconda3/envs/py37tf/lib/python3.7/inspect.py\", line 696, in getsourcefile\n",
      "    if getattr(getmodule(object, filename), '__loader__', None) is not None:\n",
      "  File \"/Users/taylorschneider/opt/anaconda3/envs/py37tf/lib/python3.7/inspect.py\", line 733, in getmodule\n",
      "    if ismodule(module) and hasattr(module, '__file__'):\n",
      "  File \"/Users/taylorschneider/opt/anaconda3/envs/py37tf/lib/python3.7/site-packages/tensorflow/__init__.py\", line 50, in __getattr__\n",
      "    module = self._load()\n",
      "  File \"/Users/taylorschneider/opt/anaconda3/envs/py37tf/lib/python3.7/site-packages/tensorflow/__init__.py\", line 44, in _load\n",
      "    module = _importlib.import_module(self.__name__)\n",
      "  File \"/Users/taylorschneider/opt/anaconda3/envs/py37tf/lib/python3.7/importlib/__init__.py\", line 127, in import_module\n",
      "    return _bootstrap._gcd_import(name[level:], package, level)\n",
      "  File \"<frozen importlib._bootstrap>\", line 1006, in _gcd_import\n",
      "  File \"<frozen importlib._bootstrap>\", line 983, in _find_and_load\n",
      "  File \"<frozen importlib._bootstrap>\", line 967, in _find_and_load_unlocked\n",
      "  File \"<frozen importlib._bootstrap>\", line 677, in _load_unlocked\n",
      "  File \"<frozen importlib._bootstrap_external>\", line 728, in exec_module\n",
      "  File \"<frozen importlib._bootstrap>\", line 219, in _call_with_frames_removed\n",
      "  File \"/Users/taylorschneider/opt/anaconda3/envs/py37tf/lib/python3.7/site-packages/tensorflow_core/contrib/__init__.py\", line 39, in <module>\n",
      "    from tensorflow.contrib import compiler\n",
      "  File \"/Users/taylorschneider/opt/anaconda3/envs/py37tf/lib/python3.7/site-packages/tensorflow_core/contrib/compiler/__init__.py\", line 21, in <module>\n",
      "    from tensorflow.contrib.compiler import jit\n",
      "  File \"/Users/taylorschneider/opt/anaconda3/envs/py37tf/lib/python3.7/site-packages/tensorflow_core/contrib/compiler/__init__.py\", line 22, in <module>\n",
      "    from tensorflow.contrib.compiler import xla\n",
      "  File \"/Users/taylorschneider/opt/anaconda3/envs/py37tf/lib/python3.7/site-packages/tensorflow_core/contrib/compiler/xla.py\", line 22, in <module>\n",
      "    from tensorflow.python.estimator import model_fn as model_fn_lib\n",
      "  File \"/Users/taylorschneider/opt/anaconda3/envs/py37tf/lib/python3.7/site-packages/tensorflow_core/python/estimator/model_fn.py\", line 26, in <module>\n",
      "    from tensorflow_estimator.python.estimator import model_fn\n",
      "  File \"/Users/taylorschneider/opt/anaconda3/envs/py37tf/lib/python3.7/site-packages/tensorflow_estimator/__init__.py\", line 10, in <module>\n",
      "    from tensorflow_estimator._api.v1 import estimator\n",
      "  File \"/Users/taylorschneider/opt/anaconda3/envs/py37tf/lib/python3.7/site-packages/tensorflow_estimator/_api/v1/estimator/__init__.py\", line 10, in <module>\n",
      "    from tensorflow_estimator._api.v1.estimator import experimental\n",
      "  File \"/Users/taylorschneider/opt/anaconda3/envs/py37tf/lib/python3.7/site-packages/tensorflow_estimator/_api/v1/estimator/experimental/__init__.py\", line 10, in <module>\n",
      "    from tensorflow_estimator.python.estimator.canned.dnn import dnn_logit_fn_builder\n",
      "  File \"/Users/taylorschneider/opt/anaconda3/envs/py37tf/lib/python3.7/site-packages/tensorflow_estimator/python/estimator/canned/dnn.py\", line 27, in <module>\n",
      "    from tensorflow_estimator.python.estimator import estimator\n",
      "  File \"/Users/taylorschneider/opt/anaconda3/envs/py37tf/lib/python3.7/site-packages/tensorflow_estimator/python/estimator/estimator.py\", line 36, in <module>\n",
      "    from tensorflow.python.profiler import trace\n",
      "ImportError: cannot import name 'trace' from 'tensorflow.python.profiler' (/Users/taylorschneider/opt/anaconda3/envs/py37tf/lib/python3.7/site-packages/tensorflow_core/python/profiler/__init__.py)\n",
      "Traceback (most recent call last):\n",
      "  File \"/Users/taylorschneider/opt/anaconda3/envs/py37tf/lib/python3.7/site-packages/IPython/core/interactiveshell.py\", line 3457, in run_code\n",
      "    exec(code_obj, self.user_global_ns, self.user_ns)\n",
      "  File \"/var/folders/mx/lrbgms150gdbdt3pfhw4t3m00000gn/T/ipykernel_1737/267833325.py\", line 5, in <module>\n",
      "    model.add(Conv2D(28, (3, 3), input_shape=(28, 28), activation='relu', padding='same'))\n",
      "  File \"/Users/taylorschneider/opt/anaconda3/envs/py37tf/lib/python3.7/site-packages/keras/engine/sequential.py\", line 166, in add\n",
      "    layer(x)\n",
      "  File \"/Users/taylorschneider/opt/anaconda3/envs/py37tf/lib/python3.7/site-packages/keras/engine/base_layer.py\", line 446, in __call__\n",
      "    self.assert_input_compatibility(inputs)\n",
      "  File \"/Users/taylorschneider/opt/anaconda3/envs/py37tf/lib/python3.7/site-packages/keras/engine/base_layer.py\", line 342, in assert_input_compatibility\n",
      "    str(K.ndim(x)))\n",
      "ValueError: Input 0 is incompatible with layer conv2d_1: expected ndim=4, found ndim=3\n",
      "\n",
      "During handling of the above exception, another exception occurred:\n",
      "\n",
      "Traceback (most recent call last):\n",
      "  File \"/Users/taylorschneider/opt/anaconda3/envs/py37tf/lib/python3.7/site-packages/IPython/core/interactiveshell.py\", line 2077, in showtraceback\n",
      "    stb = value._render_traceback_()\n",
      "AttributeError: 'ValueError' object has no attribute '_render_traceback_'\n",
      "\n",
      "During handling of the above exception, another exception occurred:\n",
      "\n",
      "Traceback (most recent call last):\n",
      "  File \"/Users/taylorschneider/opt/anaconda3/envs/py37tf/lib/python3.7/site-packages/IPython/core/interactiveshell.py\", line 3377, in run_ast_nodes\n",
      "    if (await self.run_code(code, result,  async_=asy)):\n",
      "  File \"/Users/taylorschneider/opt/anaconda3/envs/py37tf/lib/python3.7/site-packages/IPython/core/interactiveshell.py\", line 3474, in run_code\n",
      "    self.showtraceback(running_compiled_code=True)\n",
      "  File \"/Users/taylorschneider/opt/anaconda3/envs/py37tf/lib/python3.7/site-packages/IPython/core/interactiveshell.py\", line 2080, in showtraceback\n",
      "    value, tb, tb_offset=tb_offset)\n",
      "  File \"/Users/taylorschneider/opt/anaconda3/envs/py37tf/lib/python3.7/site-packages/IPython/core/ultratb.py\", line 1368, in structured_traceback\n",
      "    self, etype, value, tb, tb_offset, number_of_lines_of_context)\n",
      "  File \"/Users/taylorschneider/opt/anaconda3/envs/py37tf/lib/python3.7/site-packages/IPython/core/ultratb.py\", line 1268, in structured_traceback\n",
      "    self, etype, value, tb, tb_offset, number_of_lines_of_context\n",
      "  File \"/Users/taylorschneider/opt/anaconda3/envs/py37tf/lib/python3.7/site-packages/IPython/core/ultratb.py\", line 1125, in structured_traceback\n",
      "    tb_offset)\n",
      "  File \"/Users/taylorschneider/opt/anaconda3/envs/py37tf/lib/python3.7/site-packages/IPython/core/ultratb.py\", line 1082, in format_exception_as_a_whole\n",
      "    last_unique, recursion_repeat = find_recursion(orig_etype, evalue, records)\n",
      "  File \"/Users/taylorschneider/opt/anaconda3/envs/py37tf/lib/python3.7/site-packages/IPython/core/ultratb.py\", line 382, in find_recursion\n",
      "    return len(records), 0\n",
      "TypeError: object of type 'NoneType' has no len()\n",
      "\n",
      "During handling of the above exception, another exception occurred:\n",
      "\n",
      "Traceback (most recent call last):\n",
      "  File \"/Users/taylorschneider/opt/anaconda3/envs/py37tf/lib/python3.7/site-packages/IPython/core/interactiveshell.py\", line 2077, in showtraceback\n",
      "    stb = value._render_traceback_()\n",
      "AttributeError: 'TypeError' object has no attribute '_render_traceback_'\n",
      "\n",
      "During handling of the above exception, another exception occurred:\n",
      "\n",
      "Traceback (most recent call last):\n",
      "  File \"/Users/taylorschneider/opt/anaconda3/envs/py37tf/lib/python3.7/site-packages/IPython/core/ultratb.py\", line 1101, in get_records\n",
      "    return _fixed_getinnerframes(etb, number_of_lines_of_context, tb_offset)\n",
      "  File \"/Users/taylorschneider/opt/anaconda3/envs/py37tf/lib/python3.7/site-packages/IPython/core/ultratb.py\", line 248, in wrapped\n",
      "    return f(*args, **kwargs)\n",
      "  File \"/Users/taylorschneider/opt/anaconda3/envs/py37tf/lib/python3.7/site-packages/IPython/core/ultratb.py\", line 281, in _fixed_getinnerframes\n",
      "    records = fix_frame_records_filenames(inspect.getinnerframes(etb, context))\n",
      "  File \"/Users/taylorschneider/opt/anaconda3/envs/py37tf/lib/python3.7/inspect.py\", line 1502, in getinnerframes\n",
      "    frameinfo = (tb.tb_frame,) + getframeinfo(tb, context)\n",
      "  File \"/Users/taylorschneider/opt/anaconda3/envs/py37tf/lib/python3.7/inspect.py\", line 1460, in getframeinfo\n",
      "    filename = getsourcefile(frame) or getfile(frame)\n",
      "  File \"/Users/taylorschneider/opt/anaconda3/envs/py37tf/lib/python3.7/inspect.py\", line 696, in getsourcefile\n",
      "    if getattr(getmodule(object, filename), '__loader__', None) is not None:\n",
      "  File \"/Users/taylorschneider/opt/anaconda3/envs/py37tf/lib/python3.7/inspect.py\", line 733, in getmodule\n",
      "    if ismodule(module) and hasattr(module, '__file__'):\n",
      "  File \"/Users/taylorschneider/opt/anaconda3/envs/py37tf/lib/python3.7/site-packages/tensorflow/__init__.py\", line 50, in __getattr__\n",
      "    module = self._load()\n",
      "  File \"/Users/taylorschneider/opt/anaconda3/envs/py37tf/lib/python3.7/site-packages/tensorflow/__init__.py\", line 44, in _load\n",
      "    module = _importlib.import_module(self.__name__)\n",
      "  File \"/Users/taylorschneider/opt/anaconda3/envs/py37tf/lib/python3.7/importlib/__init__.py\", line 127, in import_module\n",
      "    return _bootstrap._gcd_import(name[level:], package, level)\n",
      "  File \"<frozen importlib._bootstrap>\", line 1006, in _gcd_import\n",
      "  File \"<frozen importlib._bootstrap>\", line 983, in _find_and_load\n",
      "  File \"<frozen importlib._bootstrap>\", line 965, in _find_and_load_unlocked\n",
      "ModuleNotFoundError: No module named 'tensorflow_core.estimator'\n",
      "Traceback (most recent call last):\n",
      "  File \"/Users/taylorschneider/opt/anaconda3/envs/py37tf/lib/python3.7/site-packages/IPython/core/interactiveshell.py\", line 3457, in run_code\n",
      "    exec(code_obj, self.user_global_ns, self.user_ns)\n",
      "  File \"/var/folders/mx/lrbgms150gdbdt3pfhw4t3m00000gn/T/ipykernel_1737/267833325.py\", line 5, in <module>\n",
      "    model.add(Conv2D(28, (3, 3), input_shape=(28, 28), activation='relu', padding='same'))\n",
      "  File \"/Users/taylorschneider/opt/anaconda3/envs/py37tf/lib/python3.7/site-packages/keras/engine/sequential.py\", line 166, in add\n",
      "    layer(x)\n",
      "  File \"/Users/taylorschneider/opt/anaconda3/envs/py37tf/lib/python3.7/site-packages/keras/engine/base_layer.py\", line 446, in __call__\n",
      "    self.assert_input_compatibility(inputs)\n",
      "  File \"/Users/taylorschneider/opt/anaconda3/envs/py37tf/lib/python3.7/site-packages/keras/engine/base_layer.py\", line 342, in assert_input_compatibility\n",
      "    str(K.ndim(x)))\n",
      "ValueError: Input 0 is incompatible with layer conv2d_1: expected ndim=4, found ndim=3\n",
      "\n",
      "During handling of the above exception, another exception occurred:\n",
      "\n",
      "Traceback (most recent call last):\n",
      "  File \"/Users/taylorschneider/opt/anaconda3/envs/py37tf/lib/python3.7/site-packages/IPython/core/interactiveshell.py\", line 2077, in showtraceback\n",
      "    stb = value._render_traceback_()\n",
      "AttributeError: 'ValueError' object has no attribute '_render_traceback_'\n",
      "\n",
      "During handling of the above exception, another exception occurred:\n",
      "\n",
      "Traceback (most recent call last):\n",
      "  File \"/Users/taylorschneider/opt/anaconda3/envs/py37tf/lib/python3.7/site-packages/IPython/core/interactiveshell.py\", line 3377, in run_ast_nodes\n",
      "    if (await self.run_code(code, result,  async_=asy)):\n",
      "  File \"/Users/taylorschneider/opt/anaconda3/envs/py37tf/lib/python3.7/site-packages/IPython/core/interactiveshell.py\", line 3474, in run_code\n",
      "    self.showtraceback(running_compiled_code=True)\n",
      "  File \"/Users/taylorschneider/opt/anaconda3/envs/py37tf/lib/python3.7/site-packages/IPython/core/interactiveshell.py\", line 2080, in showtraceback\n",
      "    value, tb, tb_offset=tb_offset)\n",
      "  File \"/Users/taylorschneider/opt/anaconda3/envs/py37tf/lib/python3.7/site-packages/IPython/core/ultratb.py\", line 1368, in structured_traceback\n",
      "    self, etype, value, tb, tb_offset, number_of_lines_of_context)\n",
      "  File \"/Users/taylorschneider/opt/anaconda3/envs/py37tf/lib/python3.7/site-packages/IPython/core/ultratb.py\", line 1268, in structured_traceback\n",
      "    self, etype, value, tb, tb_offset, number_of_lines_of_context\n",
      "  File \"/Users/taylorschneider/opt/anaconda3/envs/py37tf/lib/python3.7/site-packages/IPython/core/ultratb.py\", line 1125, in structured_traceback\n",
      "    tb_offset)\n",
      "  File \"/Users/taylorschneider/opt/anaconda3/envs/py37tf/lib/python3.7/site-packages/IPython/core/ultratb.py\", line 1082, in format_exception_as_a_whole\n",
      "    last_unique, recursion_repeat = find_recursion(orig_etype, evalue, records)\n",
      "  File \"/Users/taylorschneider/opt/anaconda3/envs/py37tf/lib/python3.7/site-packages/IPython/core/ultratb.py\", line 382, in find_recursion\n",
      "    return len(records), 0\n",
      "TypeError: object of type 'NoneType' has no len()\n",
      "\n",
      "During handling of the above exception, another exception occurred:\n",
      "\n",
      "Traceback (most recent call last):\n",
      "  File \"/Users/taylorschneider/opt/anaconda3/envs/py37tf/lib/python3.7/site-packages/IPython/core/interactiveshell.py\", line 2077, in showtraceback\n",
      "    stb = value._render_traceback_()\n",
      "AttributeError: 'TypeError' object has no attribute '_render_traceback_'\n",
      "\n",
      "During handling of the above exception, another exception occurred:\n",
      "\n",
      "Traceback (most recent call last):\n",
      "  File \"/Users/taylorschneider/opt/anaconda3/envs/py37tf/lib/python3.7/site-packages/IPython/core/interactiveshell.py\", line 2960, in _run_cell\n",
      "    return runner(coro)\n",
      "  File \"/Users/taylorschneider/opt/anaconda3/envs/py37tf/lib/python3.7/site-packages/IPython/core/async_helpers.py\", line 78, in _pseudo_sync_runner\n",
      "    coro.send(None)\n",
      "  File \"/Users/taylorschneider/opt/anaconda3/envs/py37tf/lib/python3.7/site-packages/IPython/core/interactiveshell.py\", line 3186, in run_cell_async\n",
      "    interactivity=interactivity, compiler=compiler, result=result)\n",
      "  File \"/Users/taylorschneider/opt/anaconda3/envs/py37tf/lib/python3.7/site-packages/IPython/core/interactiveshell.py\", line 3396, in run_ast_nodes\n",
      "    self.showtraceback()\n",
      "  File \"/Users/taylorschneider/opt/anaconda3/envs/py37tf/lib/python3.7/site-packages/IPython/core/interactiveshell.py\", line 2080, in showtraceback\n",
      "    value, tb, tb_offset=tb_offset)\n",
      "  File \"/Users/taylorschneider/opt/anaconda3/envs/py37tf/lib/python3.7/site-packages/IPython/core/ultratb.py\", line 1368, in structured_traceback\n",
      "    self, etype, value, tb, tb_offset, number_of_lines_of_context)\n",
      "  File \"/Users/taylorschneider/opt/anaconda3/envs/py37tf/lib/python3.7/site-packages/IPython/core/ultratb.py\", line 1268, in structured_traceback\n",
      "    self, etype, value, tb, tb_offset, number_of_lines_of_context\n",
      "  File \"/Users/taylorschneider/opt/anaconda3/envs/py37tf/lib/python3.7/site-packages/IPython/core/ultratb.py\", line 1143, in structured_traceback\n",
      "    chained_exceptions_tb_offset)\n",
      "  File \"/Users/taylorschneider/opt/anaconda3/envs/py37tf/lib/python3.7/site-packages/IPython/core/ultratb.py\", line 1082, in format_exception_as_a_whole\n",
      "    last_unique, recursion_repeat = find_recursion(orig_etype, evalue, records)\n",
      "  File \"/Users/taylorschneider/opt/anaconda3/envs/py37tf/lib/python3.7/site-packages/IPython/core/ultratb.py\", line 382, in find_recursion\n",
      "    return len(records), 0\n",
      "TypeError: object of type 'NoneType' has no len()\n",
      "\n",
      "During handling of the above exception, another exception occurred:\n",
      "\n",
      "Traceback (most recent call last):\n",
      "  File \"/Users/taylorschneider/opt/anaconda3/envs/py37tf/lib/python3.7/site-packages/IPython/core/interactiveshell.py\", line 2077, in showtraceback\n",
      "    stb = value._render_traceback_()\n",
      "AttributeError: 'TypeError' object has no attribute '_render_traceback_'\n",
      "\n",
      "During handling of the above exception, another exception occurred:\n",
      "\n",
      "Traceback (most recent call last):\n",
      "  File \"/Users/taylorschneider/opt/anaconda3/envs/py37tf/lib/python3.7/site-packages/IPython/core/ultratb.py\", line 1101, in get_records\n",
      "    return _fixed_getinnerframes(etb, number_of_lines_of_context, tb_offset)\n",
      "  File \"/Users/taylorschneider/opt/anaconda3/envs/py37tf/lib/python3.7/site-packages/IPython/core/ultratb.py\", line 248, in wrapped\n",
      "    return f(*args, **kwargs)\n",
      "  File \"/Users/taylorschneider/opt/anaconda3/envs/py37tf/lib/python3.7/site-packages/IPython/core/ultratb.py\", line 281, in _fixed_getinnerframes\n",
      "    records = fix_frame_records_filenames(inspect.getinnerframes(etb, context))\n",
      "  File \"/Users/taylorschneider/opt/anaconda3/envs/py37tf/lib/python3.7/inspect.py\", line 1502, in getinnerframes\n",
      "    frameinfo = (tb.tb_frame,) + getframeinfo(tb, context)\n",
      "  File \"/Users/taylorschneider/opt/anaconda3/envs/py37tf/lib/python3.7/inspect.py\", line 1460, in getframeinfo\n",
      "    filename = getsourcefile(frame) or getfile(frame)\n",
      "  File \"/Users/taylorschneider/opt/anaconda3/envs/py37tf/lib/python3.7/inspect.py\", line 696, in getsourcefile\n",
      "    if getattr(getmodule(object, filename), '__loader__', None) is not None:\n",
      "  File \"/Users/taylorschneider/opt/anaconda3/envs/py37tf/lib/python3.7/inspect.py\", line 733, in getmodule\n",
      "    if ismodule(module) and hasattr(module, '__file__'):\n",
      "  File \"/Users/taylorschneider/opt/anaconda3/envs/py37tf/lib/python3.7/site-packages/tensorflow/__init__.py\", line 50, in __getattr__\n",
      "    module = self._load()\n",
      "  File \"/Users/taylorschneider/opt/anaconda3/envs/py37tf/lib/python3.7/site-packages/tensorflow/__init__.py\", line 44, in _load\n",
      "    module = _importlib.import_module(self.__name__)\n",
      "  File \"/Users/taylorschneider/opt/anaconda3/envs/py37tf/lib/python3.7/importlib/__init__.py\", line 127, in import_module\n",
      "    return _bootstrap._gcd_import(name[level:], package, level)\n",
      "  File \"<frozen importlib._bootstrap>\", line 1006, in _gcd_import\n",
      "  File \"<frozen importlib._bootstrap>\", line 983, in _find_and_load\n",
      "  File \"<frozen importlib._bootstrap>\", line 965, in _find_and_load_unlocked\n",
      "ModuleNotFoundError: No module named 'tensorflow_core.estimator'\n"
     ]
    }
   ],
   "source": [
    "#Task 2 - need to update\n",
    "\n",
    "# Build a deeper CNN model\n",
    "model = Sequential()\n",
    "model.add(Conv2D(28, (3, 3), input_shape=(28, 28), activation='relu', padding='same'))\n",
    "model.add(MaxPooling2D())\n",
    "model.add(Conv2D(14, (3, 3), activation='relu', padding='same'))\n",
    "model.add(MaxPooling2D())\n",
    "model.add(Flatten())\n",
    "model.add(Dense(120, activation='relu', kernel_constraint=maxnorm(3)))\n",
    "model.add(Dense(84, activation='relu', kernel_constraint=maxnorm(3)))\n",
    "model.add(Dense(10, activation='softmax'))\n"
   ]
  },
  {
   "cell_type": "code",
   "execution_count": null,
   "id": "9850ae3a",
   "metadata": {},
   "outputs": [],
   "source": [
    "# Compile model\n",
    "model.compile(loss='categorical_crossentropy', optimizer=\"adam\", metrics=['accuracy'])"
   ]
  },
  {
   "cell_type": "code",
   "execution_count": null,
   "id": "c7ef024b",
   "metadata": {},
   "outputs": [],
   "source": [
    "#train model\n",
    "tf.set_random_seed(1)\n",
    "np.random.seed(1)\n",
    "\n",
    "epochs = 20"
   ]
  },
  {
   "cell_type": "code",
   "execution_count": null,
   "id": "8704cf58",
   "metadata": {},
   "outputs": [],
   "source": [
    "# Fit the model\n",
    "model.fit(x_train, y_train, validation_data=(x_test, y_test), epochs=epochs, batch_size=32, verbose=1)"
   ]
  },
  {
   "cell_type": "code",
   "execution_count": null,
   "id": "272151af",
   "metadata": {},
   "outputs": [],
   "source": [
    "# Evaluate Model\n",
    "scores = model.evaluate(x_test, y_test, verbose=0)\n",
    "print(\"Accuracy: %.2f%%\" % (scores[1]*100))"
   ]
  }
 ],
 "metadata": {
  "kernelspec": {
   "display_name": "Python 3 (ipykernel)",
   "language": "python",
   "name": "python3"
  },
  "language_info": {
   "codemirror_mode": {
    "name": "ipython",
    "version": 3
   },
   "file_extension": ".py",
   "mimetype": "text/x-python",
   "name": "python",
   "nbconvert_exporter": "python",
   "pygments_lexer": "ipython3",
   "version": "3.7.13"
  }
 },
 "nbformat": 4,
 "nbformat_minor": 5
}
