{
 "cells": [
  {
   "cell_type": "code",
   "execution_count": 14,
   "id": "63431763",
   "metadata": {},
   "outputs": [],
   "source": [
    "from keras.datasets import fashion_mnist\n",
    "(x_train, y_train), (x_test, y_test) = fashion_mnist.load_data()\n",
    "\n",
    "# reshape dataset to have a single channel\n",
    "x_train = x_train.reshape((x_train.shape[0], 28, 28, 1))\n",
    "x_test = x_test.reshape((x_test.shape[0], 28, 28, 1))"
   ]
  },
  {
   "cell_type": "code",
   "execution_count": 18,
   "id": "eca39a5f",
   "metadata": {},
   "outputs": [],
   "source": [
    "#packages\n",
    "import numpy as np\n",
    "import pandas as pd\n",
    "import tensorflow as tf\n",
    "import sklearn as sk\n",
    "from keras.models import Sequential\n",
    "from keras.layers import Dense\n",
    "from keras.utils import to_categorical\n",
    "from keras.models import Sequential\n",
    "from keras.layers import Dense\n",
    "from keras.models import model_from_json\n",
    "import matplotlib.pyplot as plt\n",
    "from sklearn.model_selection import train_test_split\n",
    "\n",
    "np.random.seed(1)"
   ]
  },
  {
   "cell_type": "code",
   "execution_count": 19,
   "id": "113460e7",
   "metadata": {},
   "outputs": [],
   "source": [
    "# normalize inputs \n",
    "x_train = x_train.astype('float32')\n",
    "x_test = x_test.astype('float32')\n",
    "x_train = x_train / 255.0 \n",
    "x_test = x_test / 255.0"
   ]
  },
  {
   "cell_type": "code",
   "execution_count": null,
   "id": "ab777611",
   "metadata": {},
   "outputs": [
    {
     "name": "stderr",
     "output_type": "stream",
     "text": [
      "ERROR:root:Internal Python error in the inspect module.\n",
      "Below is the traceback from this internal error.\n",
      "\n",
      "ERROR:root:Internal Python error in the inspect module.\n",
      "Below is the traceback from this internal error.\n",
      "\n",
      "ERROR:root:Internal Python error in the inspect module.\n",
      "Below is the traceback from this internal error.\n",
      "\n"
     ]
    },
    {
     "name": "stdout",
     "output_type": "stream",
     "text": [
      "ERROR! Session/line number was not unique in database. History logging moved to new session 333\n",
      "Traceback (most recent call last):\n",
      "  File \"/Users/taylorschneider/opt/anaconda3/envs/py37tf/lib/python3.7/site-packages/IPython/core/interactiveshell.py\", line 3457, in run_code\n",
      "    exec(code_obj, self.user_global_ns, self.user_ns)\n",
      "  File \"/var/folders/mx/lrbgms150gdbdt3pfhw4t3m00000gn/T/ipykernel_1380/3081945111.py\", line 3, in <module>\n",
      "    model.add(Flatten(input_shape=28))\n",
      "NameError: name 'Flatten' is not defined\n",
      "\n",
      "During handling of the above exception, another exception occurred:\n",
      "\n",
      "Traceback (most recent call last):\n",
      "  File \"/Users/taylorschneider/opt/anaconda3/envs/py37tf/lib/python3.7/site-packages/IPython/core/interactiveshell.py\", line 2077, in showtraceback\n",
      "    stb = value._render_traceback_()\n",
      "AttributeError: 'NameError' object has no attribute '_render_traceback_'\n",
      "\n",
      "During handling of the above exception, another exception occurred:\n",
      "\n",
      "Traceback (most recent call last):\n",
      "  File \"/Users/taylorschneider/opt/anaconda3/envs/py37tf/lib/python3.7/site-packages/IPython/core/ultratb.py\", line 1101, in get_records\n",
      "    return _fixed_getinnerframes(etb, number_of_lines_of_context, tb_offset)\n",
      "  File \"/Users/taylorschneider/opt/anaconda3/envs/py37tf/lib/python3.7/site-packages/IPython/core/ultratb.py\", line 248, in wrapped\n",
      "    return f(*args, **kwargs)\n",
      "  File \"/Users/taylorschneider/opt/anaconda3/envs/py37tf/lib/python3.7/site-packages/IPython/core/ultratb.py\", line 281, in _fixed_getinnerframes\n",
      "    records = fix_frame_records_filenames(inspect.getinnerframes(etb, context))\n",
      "  File \"/Users/taylorschneider/opt/anaconda3/envs/py37tf/lib/python3.7/inspect.py\", line 1502, in getinnerframes\n",
      "    frameinfo = (tb.tb_frame,) + getframeinfo(tb, context)\n",
      "  File \"/Users/taylorschneider/opt/anaconda3/envs/py37tf/lib/python3.7/inspect.py\", line 1460, in getframeinfo\n",
      "    filename = getsourcefile(frame) or getfile(frame)\n",
      "  File \"/Users/taylorschneider/opt/anaconda3/envs/py37tf/lib/python3.7/inspect.py\", line 696, in getsourcefile\n",
      "    if getattr(getmodule(object, filename), '__loader__', None) is not None:\n",
      "  File \"/Users/taylorschneider/opt/anaconda3/envs/py37tf/lib/python3.7/inspect.py\", line 733, in getmodule\n",
      "    if ismodule(module) and hasattr(module, '__file__'):\n",
      "  File \"/Users/taylorschneider/opt/anaconda3/envs/py37tf/lib/python3.7/site-packages/tensorflow/__init__.py\", line 50, in __getattr__\n",
      "    module = self._load()\n",
      "  File \"/Users/taylorschneider/opt/anaconda3/envs/py37tf/lib/python3.7/site-packages/tensorflow/__init__.py\", line 44, in _load\n",
      "    module = _importlib.import_module(self.__name__)\n",
      "  File \"/Users/taylorschneider/opt/anaconda3/envs/py37tf/lib/python3.7/importlib/__init__.py\", line 127, in import_module\n",
      "    return _bootstrap._gcd_import(name[level:], package, level)\n",
      "  File \"<frozen importlib._bootstrap>\", line 1006, in _gcd_import\n",
      "  File \"<frozen importlib._bootstrap>\", line 983, in _find_and_load\n",
      "  File \"<frozen importlib._bootstrap>\", line 965, in _find_and_load_unlocked\n",
      "ModuleNotFoundError: No module named 'tensorflow_core.estimator'\n",
      "Traceback (most recent call last):\n",
      "  File \"/Users/taylorschneider/opt/anaconda3/envs/py37tf/lib/python3.7/site-packages/IPython/core/interactiveshell.py\", line 3457, in run_code\n",
      "    exec(code_obj, self.user_global_ns, self.user_ns)\n",
      "  File \"/var/folders/mx/lrbgms150gdbdt3pfhw4t3m00000gn/T/ipykernel_1380/3081945111.py\", line 3, in <module>\n",
      "    model.add(Flatten(input_shape=28))\n",
      "NameError: name 'Flatten' is not defined\n",
      "\n",
      "During handling of the above exception, another exception occurred:\n",
      "\n",
      "Traceback (most recent call last):\n",
      "  File \"/Users/taylorschneider/opt/anaconda3/envs/py37tf/lib/python3.7/site-packages/IPython/core/interactiveshell.py\", line 2077, in showtraceback\n",
      "    stb = value._render_traceback_()\n",
      "AttributeError: 'NameError' object has no attribute '_render_traceback_'\n",
      "\n",
      "During handling of the above exception, another exception occurred:\n",
      "\n",
      "Traceback (most recent call last):\n",
      "  File \"/Users/taylorschneider/opt/anaconda3/envs/py37tf/lib/python3.7/site-packages/IPython/core/interactiveshell.py\", line 3377, in run_ast_nodes\n",
      "    if (await self.run_code(code, result,  async_=asy)):\n",
      "  File \"/Users/taylorschneider/opt/anaconda3/envs/py37tf/lib/python3.7/site-packages/IPython/core/interactiveshell.py\", line 3474, in run_code\n",
      "    self.showtraceback(running_compiled_code=True)\n",
      "  File \"/Users/taylorschneider/opt/anaconda3/envs/py37tf/lib/python3.7/site-packages/IPython/core/interactiveshell.py\", line 2080, in showtraceback\n",
      "    value, tb, tb_offset=tb_offset)\n",
      "  File \"/Users/taylorschneider/opt/anaconda3/envs/py37tf/lib/python3.7/site-packages/IPython/core/ultratb.py\", line 1368, in structured_traceback\n",
      "    self, etype, value, tb, tb_offset, number_of_lines_of_context)\n",
      "  File \"/Users/taylorschneider/opt/anaconda3/envs/py37tf/lib/python3.7/site-packages/IPython/core/ultratb.py\", line 1268, in structured_traceback\n",
      "    self, etype, value, tb, tb_offset, number_of_lines_of_context\n",
      "  File \"/Users/taylorschneider/opt/anaconda3/envs/py37tf/lib/python3.7/site-packages/IPython/core/ultratb.py\", line 1125, in structured_traceback\n",
      "    tb_offset)\n",
      "  File \"/Users/taylorschneider/opt/anaconda3/envs/py37tf/lib/python3.7/site-packages/IPython/core/ultratb.py\", line 1082, in format_exception_as_a_whole\n",
      "    last_unique, recursion_repeat = find_recursion(orig_etype, evalue, records)\n",
      "  File \"/Users/taylorschneider/opt/anaconda3/envs/py37tf/lib/python3.7/site-packages/IPython/core/ultratb.py\", line 382, in find_recursion\n",
      "    return len(records), 0\n",
      "TypeError: object of type 'NoneType' has no len()\n",
      "\n",
      "During handling of the above exception, another exception occurred:\n",
      "\n",
      "Traceback (most recent call last):\n",
      "  File \"/Users/taylorschneider/opt/anaconda3/envs/py37tf/lib/python3.7/site-packages/IPython/core/interactiveshell.py\", line 2077, in showtraceback\n",
      "    stb = value._render_traceback_()\n",
      "AttributeError: 'TypeError' object has no attribute '_render_traceback_'\n",
      "\n",
      "During handling of the above exception, another exception occurred:\n",
      "\n",
      "Traceback (most recent call last):\n",
      "  File \"/Users/taylorschneider/opt/anaconda3/envs/py37tf/lib/python3.7/site-packages/IPython/core/ultratb.py\", line 1101, in get_records\n",
      "    return _fixed_getinnerframes(etb, number_of_lines_of_context, tb_offset)\n",
      "  File \"/Users/taylorschneider/opt/anaconda3/envs/py37tf/lib/python3.7/site-packages/IPython/core/ultratb.py\", line 248, in wrapped\n",
      "    return f(*args, **kwargs)\n",
      "  File \"/Users/taylorschneider/opt/anaconda3/envs/py37tf/lib/python3.7/site-packages/IPython/core/ultratb.py\", line 281, in _fixed_getinnerframes\n",
      "    records = fix_frame_records_filenames(inspect.getinnerframes(etb, context))\n",
      "  File \"/Users/taylorschneider/opt/anaconda3/envs/py37tf/lib/python3.7/inspect.py\", line 1502, in getinnerframes\n",
      "    frameinfo = (tb.tb_frame,) + getframeinfo(tb, context)\n",
      "  File \"/Users/taylorschneider/opt/anaconda3/envs/py37tf/lib/python3.7/inspect.py\", line 1460, in getframeinfo\n",
      "    filename = getsourcefile(frame) or getfile(frame)\n",
      "  File \"/Users/taylorschneider/opt/anaconda3/envs/py37tf/lib/python3.7/inspect.py\", line 696, in getsourcefile\n",
      "    if getattr(getmodule(object, filename), '__loader__', None) is not None:\n",
      "  File \"/Users/taylorschneider/opt/anaconda3/envs/py37tf/lib/python3.7/inspect.py\", line 733, in getmodule\n",
      "    if ismodule(module) and hasattr(module, '__file__'):\n",
      "  File \"/Users/taylorschneider/opt/anaconda3/envs/py37tf/lib/python3.7/site-packages/tensorflow/__init__.py\", line 50, in __getattr__\n",
      "    module = self._load()\n",
      "  File \"/Users/taylorschneider/opt/anaconda3/envs/py37tf/lib/python3.7/site-packages/tensorflow/__init__.py\", line 44, in _load\n",
      "    module = _importlib.import_module(self.__name__)\n",
      "  File \"/Users/taylorschneider/opt/anaconda3/envs/py37tf/lib/python3.7/importlib/__init__.py\", line 127, in import_module\n",
      "    return _bootstrap._gcd_import(name[level:], package, level)\n",
      "  File \"<frozen importlib._bootstrap>\", line 1006, in _gcd_import\n",
      "  File \"<frozen importlib._bootstrap>\", line 983, in _find_and_load\n",
      "  File \"<frozen importlib._bootstrap>\", line 965, in _find_and_load_unlocked\n",
      "ModuleNotFoundError: No module named 'tensorflow_core.estimator'\n",
      "Traceback (most recent call last):\n",
      "  File \"/Users/taylorschneider/opt/anaconda3/envs/py37tf/lib/python3.7/site-packages/IPython/core/interactiveshell.py\", line 3457, in run_code\n",
      "    exec(code_obj, self.user_global_ns, self.user_ns)\n",
      "  File \"/var/folders/mx/lrbgms150gdbdt3pfhw4t3m00000gn/T/ipykernel_1380/3081945111.py\", line 3, in <module>\n",
      "    model.add(Flatten(input_shape=28))\n",
      "NameError: name 'Flatten' is not defined\n",
      "\n",
      "During handling of the above exception, another exception occurred:\n",
      "\n",
      "Traceback (most recent call last):\n",
      "  File \"/Users/taylorschneider/opt/anaconda3/envs/py37tf/lib/python3.7/site-packages/IPython/core/interactiveshell.py\", line 2077, in showtraceback\n",
      "    stb = value._render_traceback_()\n",
      "AttributeError: 'NameError' object has no attribute '_render_traceback_'\n",
      "\n",
      "During handling of the above exception, another exception occurred:\n",
      "\n",
      "Traceback (most recent call last):\n",
      "  File \"/Users/taylorschneider/opt/anaconda3/envs/py37tf/lib/python3.7/site-packages/IPython/core/interactiveshell.py\", line 3377, in run_ast_nodes\n",
      "    if (await self.run_code(code, result,  async_=asy)):\n",
      "  File \"/Users/taylorschneider/opt/anaconda3/envs/py37tf/lib/python3.7/site-packages/IPython/core/interactiveshell.py\", line 3474, in run_code\n",
      "    self.showtraceback(running_compiled_code=True)\n",
      "  File \"/Users/taylorschneider/opt/anaconda3/envs/py37tf/lib/python3.7/site-packages/IPython/core/interactiveshell.py\", line 2080, in showtraceback\n",
      "    value, tb, tb_offset=tb_offset)\n",
      "  File \"/Users/taylorschneider/opt/anaconda3/envs/py37tf/lib/python3.7/site-packages/IPython/core/ultratb.py\", line 1368, in structured_traceback\n",
      "    self, etype, value, tb, tb_offset, number_of_lines_of_context)\n",
      "  File \"/Users/taylorschneider/opt/anaconda3/envs/py37tf/lib/python3.7/site-packages/IPython/core/ultratb.py\", line 1268, in structured_traceback\n",
      "    self, etype, value, tb, tb_offset, number_of_lines_of_context\n",
      "  File \"/Users/taylorschneider/opt/anaconda3/envs/py37tf/lib/python3.7/site-packages/IPython/core/ultratb.py\", line 1125, in structured_traceback\n",
      "    tb_offset)\n",
      "  File \"/Users/taylorschneider/opt/anaconda3/envs/py37tf/lib/python3.7/site-packages/IPython/core/ultratb.py\", line 1082, in format_exception_as_a_whole\n",
      "    last_unique, recursion_repeat = find_recursion(orig_etype, evalue, records)\n",
      "  File \"/Users/taylorschneider/opt/anaconda3/envs/py37tf/lib/python3.7/site-packages/IPython/core/ultratb.py\", line 382, in find_recursion\n",
      "    return len(records), 0\n",
      "TypeError: object of type 'NoneType' has no len()\n",
      "\n",
      "During handling of the above exception, another exception occurred:\n",
      "\n",
      "Traceback (most recent call last):\n",
      "  File \"/Users/taylorschneider/opt/anaconda3/envs/py37tf/lib/python3.7/site-packages/IPython/core/interactiveshell.py\", line 2077, in showtraceback\n",
      "    stb = value._render_traceback_()\n",
      "AttributeError: 'TypeError' object has no attribute '_render_traceback_'\n",
      "\n",
      "During handling of the above exception, another exception occurred:\n",
      "\n",
      "Traceback (most recent call last):\n",
      "  File \"/Users/taylorschneider/opt/anaconda3/envs/py37tf/lib/python3.7/site-packages/IPython/core/interactiveshell.py\", line 2960, in _run_cell\n",
      "    return runner(coro)\n",
      "  File \"/Users/taylorschneider/opt/anaconda3/envs/py37tf/lib/python3.7/site-packages/IPython/core/async_helpers.py\", line 78, in _pseudo_sync_runner\n",
      "    coro.send(None)\n",
      "  File \"/Users/taylorschneider/opt/anaconda3/envs/py37tf/lib/python3.7/site-packages/IPython/core/interactiveshell.py\", line 3186, in run_cell_async\n",
      "    interactivity=interactivity, compiler=compiler, result=result)\n",
      "  File \"/Users/taylorschneider/opt/anaconda3/envs/py37tf/lib/python3.7/site-packages/IPython/core/interactiveshell.py\", line 3396, in run_ast_nodes\n",
      "    self.showtraceback()\n",
      "  File \"/Users/taylorschneider/opt/anaconda3/envs/py37tf/lib/python3.7/site-packages/IPython/core/interactiveshell.py\", line 2080, in showtraceback\n",
      "    value, tb, tb_offset=tb_offset)\n",
      "  File \"/Users/taylorschneider/opt/anaconda3/envs/py37tf/lib/python3.7/site-packages/IPython/core/ultratb.py\", line 1368, in structured_traceback\n",
      "    self, etype, value, tb, tb_offset, number_of_lines_of_context)\n",
      "  File \"/Users/taylorschneider/opt/anaconda3/envs/py37tf/lib/python3.7/site-packages/IPython/core/ultratb.py\", line 1268, in structured_traceback\n",
      "    self, etype, value, tb, tb_offset, number_of_lines_of_context\n",
      "  File \"/Users/taylorschneider/opt/anaconda3/envs/py37tf/lib/python3.7/site-packages/IPython/core/ultratb.py\", line 1143, in structured_traceback\n",
      "    chained_exceptions_tb_offset)\n",
      "  File \"/Users/taylorschneider/opt/anaconda3/envs/py37tf/lib/python3.7/site-packages/IPython/core/ultratb.py\", line 1082, in format_exception_as_a_whole\n",
      "    last_unique, recursion_repeat = find_recursion(orig_etype, evalue, records)\n",
      "  File \"/Users/taylorschneider/opt/anaconda3/envs/py37tf/lib/python3.7/site-packages/IPython/core/ultratb.py\", line 382, in find_recursion\n",
      "    return len(records), 0\n",
      "TypeError: object of type 'NoneType' has no len()\n",
      "\n",
      "During handling of the above exception, another exception occurred:\n",
      "\n",
      "Traceback (most recent call last):\n",
      "  File \"/Users/taylorschneider/opt/anaconda3/envs/py37tf/lib/python3.7/site-packages/IPython/core/interactiveshell.py\", line 2077, in showtraceback\n",
      "    stb = value._render_traceback_()\n",
      "AttributeError: 'TypeError' object has no attribute '_render_traceback_'\n",
      "\n",
      "During handling of the above exception, another exception occurred:\n",
      "\n",
      "Traceback (most recent call last):\n",
      "  File \"/Users/taylorschneider/opt/anaconda3/envs/py37tf/lib/python3.7/site-packages/IPython/core/ultratb.py\", line 1101, in get_records\n",
      "    return _fixed_getinnerframes(etb, number_of_lines_of_context, tb_offset)\n",
      "  File \"/Users/taylorschneider/opt/anaconda3/envs/py37tf/lib/python3.7/site-packages/IPython/core/ultratb.py\", line 248, in wrapped\n",
      "    return f(*args, **kwargs)\n",
      "  File \"/Users/taylorschneider/opt/anaconda3/envs/py37tf/lib/python3.7/site-packages/IPython/core/ultratb.py\", line 281, in _fixed_getinnerframes\n",
      "    records = fix_frame_records_filenames(inspect.getinnerframes(etb, context))\n",
      "  File \"/Users/taylorschneider/opt/anaconda3/envs/py37tf/lib/python3.7/inspect.py\", line 1502, in getinnerframes\n",
      "    frameinfo = (tb.tb_frame,) + getframeinfo(tb, context)\n",
      "  File \"/Users/taylorschneider/opt/anaconda3/envs/py37tf/lib/python3.7/inspect.py\", line 1460, in getframeinfo\n",
      "    filename = getsourcefile(frame) or getfile(frame)\n",
      "  File \"/Users/taylorschneider/opt/anaconda3/envs/py37tf/lib/python3.7/inspect.py\", line 696, in getsourcefile\n",
      "    if getattr(getmodule(object, filename), '__loader__', None) is not None:\n",
      "  File \"/Users/taylorschneider/opt/anaconda3/envs/py37tf/lib/python3.7/inspect.py\", line 733, in getmodule\n",
      "    if ismodule(module) and hasattr(module, '__file__'):\n",
      "  File \"/Users/taylorschneider/opt/anaconda3/envs/py37tf/lib/python3.7/site-packages/tensorflow/__init__.py\", line 50, in __getattr__\n",
      "    module = self._load()\n",
      "  File \"/Users/taylorschneider/opt/anaconda3/envs/py37tf/lib/python3.7/site-packages/tensorflow/__init__.py\", line 44, in _load\n",
      "    module = _importlib.import_module(self.__name__)\n",
      "  File \"/Users/taylorschneider/opt/anaconda3/envs/py37tf/lib/python3.7/importlib/__init__.py\", line 127, in import_module\n",
      "    return _bootstrap._gcd_import(name[level:], package, level)\n",
      "  File \"<frozen importlib._bootstrap>\", line 1006, in _gcd_import\n",
      "  File \"<frozen importlib._bootstrap>\", line 983, in _find_and_load\n",
      "  File \"<frozen importlib._bootstrap>\", line 965, in _find_and_load_unlocked\n",
      "ModuleNotFoundError: No module named 'tensorflow_core.estimator'\n"
     ]
    }
   ],
   "source": [
    "#define model\n",
    "model = Sequential()\n",
    "model.add(Flatten(input_shape=28))\n",
    "model.add(Dense(512, activation='relu'))\n",
    "model.add(Dropout(.2))\n",
    "model.add(Dense(10, activation='softmax'))\n"
   ]
  },
  {
   "cell_type": "code",
   "execution_count": 21,
   "id": "e42a21ce",
   "metadata": {},
   "outputs": [],
   "source": [
    "# Compile model\n",
    "model.compile(loss='categorical_crossentropy', optimizer=\"adam\", metrics=['accuracy'])"
   ]
  },
  {
   "cell_type": "code",
   "execution_count": null,
   "id": "7c98c8fe",
   "metadata": {},
   "outputs": [
    {
     "name": "stderr",
     "output_type": "stream",
     "text": [
      "ERROR:root:Internal Python error in the inspect module.\n",
      "Below is the traceback from this internal error.\n",
      "\n",
      "ERROR:root:Internal Python error in the inspect module.\n",
      "Below is the traceback from this internal error.\n",
      "\n",
      "ERROR:root:Internal Python error in the inspect module.\n",
      "Below is the traceback from this internal error.\n",
      "\n"
     ]
    },
    {
     "name": "stdout",
     "output_type": "stream",
     "text": [
      "ERROR! Session/line number was not unique in database. History logging moved to new session 331\n",
      "Traceback (most recent call last):\n",
      "  File \"/Users/taylorschneider/opt/anaconda3/envs/py37tf/lib/python3.7/site-packages/IPython/core/interactiveshell.py\", line 3457, in run_code\n",
      "    exec(code_obj, self.user_global_ns, self.user_ns)\n",
      "  File \"/var/folders/mx/lrbgms150gdbdt3pfhw4t3m00000gn/T/ipykernel_1380/679738915.py\", line 7, in <module>\n",
      "    history = model.fit(x_train, y_train, epochs=epochs, batch_size=100, validation_split=0.1, verbose=0) # use 10% of training dataset for validation\n",
      "  File \"/Users/taylorschneider/opt/anaconda3/envs/py37tf/lib/python3.7/site-packages/keras/engine/training.py\", line 1154, in fit\n",
      "    batch_size=batch_size)\n",
      "  File \"/Users/taylorschneider/opt/anaconda3/envs/py37tf/lib/python3.7/site-packages/keras/engine/training.py\", line 621, in _standardize_user_data\n",
      "    exception_prefix='target')\n",
      "  File \"/Users/taylorschneider/opt/anaconda3/envs/py37tf/lib/python3.7/site-packages/keras/engine/training_utils.py\", line 135, in standardize_input_data\n",
      "    'with shape ' + str(data_shape))\n",
      "ValueError: Error when checking target: expected sequential_9_input to have 4 dimensions, but got array with shape (60000, 1)\n",
      "\n",
      "During handling of the above exception, another exception occurred:\n",
      "\n",
      "Traceback (most recent call last):\n",
      "  File \"/Users/taylorschneider/opt/anaconda3/envs/py37tf/lib/python3.7/site-packages/IPython/core/interactiveshell.py\", line 2077, in showtraceback\n",
      "    stb = value._render_traceback_()\n",
      "AttributeError: 'ValueError' object has no attribute '_render_traceback_'\n",
      "\n",
      "During handling of the above exception, another exception occurred:\n",
      "\n",
      "Traceback (most recent call last):\n",
      "  File \"/Users/taylorschneider/opt/anaconda3/envs/py37tf/lib/python3.7/site-packages/IPython/core/ultratb.py\", line 1101, in get_records\n",
      "    return _fixed_getinnerframes(etb, number_of_lines_of_context, tb_offset)\n",
      "  File \"/Users/taylorschneider/opt/anaconda3/envs/py37tf/lib/python3.7/site-packages/IPython/core/ultratb.py\", line 248, in wrapped\n",
      "    return f(*args, **kwargs)\n",
      "  File \"/Users/taylorschneider/opt/anaconda3/envs/py37tf/lib/python3.7/site-packages/IPython/core/ultratb.py\", line 281, in _fixed_getinnerframes\n",
      "    records = fix_frame_records_filenames(inspect.getinnerframes(etb, context))\n",
      "  File \"/Users/taylorschneider/opt/anaconda3/envs/py37tf/lib/python3.7/inspect.py\", line 1502, in getinnerframes\n",
      "    frameinfo = (tb.tb_frame,) + getframeinfo(tb, context)\n",
      "  File \"/Users/taylorschneider/opt/anaconda3/envs/py37tf/lib/python3.7/inspect.py\", line 1460, in getframeinfo\n",
      "    filename = getsourcefile(frame) or getfile(frame)\n",
      "  File \"/Users/taylorschneider/opt/anaconda3/envs/py37tf/lib/python3.7/inspect.py\", line 696, in getsourcefile\n",
      "    if getattr(getmodule(object, filename), '__loader__', None) is not None:\n",
      "  File \"/Users/taylorschneider/opt/anaconda3/envs/py37tf/lib/python3.7/inspect.py\", line 733, in getmodule\n",
      "    if ismodule(module) and hasattr(module, '__file__'):\n",
      "  File \"/Users/taylorschneider/opt/anaconda3/envs/py37tf/lib/python3.7/site-packages/tensorflow/__init__.py\", line 50, in __getattr__\n",
      "    module = self._load()\n",
      "  File \"/Users/taylorschneider/opt/anaconda3/envs/py37tf/lib/python3.7/site-packages/tensorflow/__init__.py\", line 44, in _load\n",
      "    module = _importlib.import_module(self.__name__)\n",
      "  File \"/Users/taylorschneider/opt/anaconda3/envs/py37tf/lib/python3.7/importlib/__init__.py\", line 127, in import_module\n",
      "    return _bootstrap._gcd_import(name[level:], package, level)\n",
      "  File \"<frozen importlib._bootstrap>\", line 1006, in _gcd_import\n",
      "  File \"<frozen importlib._bootstrap>\", line 983, in _find_and_load\n",
      "  File \"<frozen importlib._bootstrap>\", line 965, in _find_and_load_unlocked\n",
      "ModuleNotFoundError: No module named 'tensorflow_core.estimator'\n",
      "Traceback (most recent call last):\n",
      "  File \"/Users/taylorschneider/opt/anaconda3/envs/py37tf/lib/python3.7/site-packages/IPython/core/interactiveshell.py\", line 3457, in run_code\n",
      "    exec(code_obj, self.user_global_ns, self.user_ns)\n",
      "  File \"/var/folders/mx/lrbgms150gdbdt3pfhw4t3m00000gn/T/ipykernel_1380/679738915.py\", line 7, in <module>\n",
      "    history = model.fit(x_train, y_train, epochs=epochs, batch_size=100, validation_split=0.1, verbose=0) # use 10% of training dataset for validation\n",
      "  File \"/Users/taylorschneider/opt/anaconda3/envs/py37tf/lib/python3.7/site-packages/keras/engine/training.py\", line 1154, in fit\n",
      "    batch_size=batch_size)\n",
      "  File \"/Users/taylorschneider/opt/anaconda3/envs/py37tf/lib/python3.7/site-packages/keras/engine/training.py\", line 621, in _standardize_user_data\n",
      "    exception_prefix='target')\n",
      "  File \"/Users/taylorschneider/opt/anaconda3/envs/py37tf/lib/python3.7/site-packages/keras/engine/training_utils.py\", line 135, in standardize_input_data\n",
      "    'with shape ' + str(data_shape))\n",
      "ValueError: Error when checking target: expected sequential_9_input to have 4 dimensions, but got array with shape (60000, 1)\n",
      "\n",
      "During handling of the above exception, another exception occurred:\n",
      "\n",
      "Traceback (most recent call last):\n",
      "  File \"/Users/taylorschneider/opt/anaconda3/envs/py37tf/lib/python3.7/site-packages/IPython/core/interactiveshell.py\", line 2077, in showtraceback\n",
      "    stb = value._render_traceback_()\n",
      "AttributeError: 'ValueError' object has no attribute '_render_traceback_'\n",
      "\n",
      "During handling of the above exception, another exception occurred:\n",
      "\n",
      "Traceback (most recent call last):\n",
      "  File \"/Users/taylorschneider/opt/anaconda3/envs/py37tf/lib/python3.7/site-packages/IPython/core/interactiveshell.py\", line 3377, in run_ast_nodes\n",
      "    if (await self.run_code(code, result,  async_=asy)):\n",
      "  File \"/Users/taylorschneider/opt/anaconda3/envs/py37tf/lib/python3.7/site-packages/IPython/core/interactiveshell.py\", line 3474, in run_code\n",
      "    self.showtraceback(running_compiled_code=True)\n",
      "  File \"/Users/taylorschneider/opt/anaconda3/envs/py37tf/lib/python3.7/site-packages/IPython/core/interactiveshell.py\", line 2080, in showtraceback\n",
      "    value, tb, tb_offset=tb_offset)\n",
      "  File \"/Users/taylorschneider/opt/anaconda3/envs/py37tf/lib/python3.7/site-packages/IPython/core/ultratb.py\", line 1368, in structured_traceback\n",
      "    self, etype, value, tb, tb_offset, number_of_lines_of_context)\n",
      "  File \"/Users/taylorschneider/opt/anaconda3/envs/py37tf/lib/python3.7/site-packages/IPython/core/ultratb.py\", line 1268, in structured_traceback\n",
      "    self, etype, value, tb, tb_offset, number_of_lines_of_context\n",
      "  File \"/Users/taylorschneider/opt/anaconda3/envs/py37tf/lib/python3.7/site-packages/IPython/core/ultratb.py\", line 1125, in structured_traceback\n",
      "    tb_offset)\n",
      "  File \"/Users/taylorschneider/opt/anaconda3/envs/py37tf/lib/python3.7/site-packages/IPython/core/ultratb.py\", line 1082, in format_exception_as_a_whole\n",
      "    last_unique, recursion_repeat = find_recursion(orig_etype, evalue, records)\n",
      "  File \"/Users/taylorschneider/opt/anaconda3/envs/py37tf/lib/python3.7/site-packages/IPython/core/ultratb.py\", line 382, in find_recursion\n",
      "    return len(records), 0\n",
      "TypeError: object of type 'NoneType' has no len()\n",
      "\n",
      "During handling of the above exception, another exception occurred:\n",
      "\n",
      "Traceback (most recent call last):\n",
      "  File \"/Users/taylorschneider/opt/anaconda3/envs/py37tf/lib/python3.7/site-packages/IPython/core/interactiveshell.py\", line 2077, in showtraceback\n",
      "    stb = value._render_traceback_()\n",
      "AttributeError: 'TypeError' object has no attribute '_render_traceback_'\n",
      "\n",
      "During handling of the above exception, another exception occurred:\n",
      "\n",
      "Traceback (most recent call last):\n",
      "  File \"/Users/taylorschneider/opt/anaconda3/envs/py37tf/lib/python3.7/site-packages/IPython/core/ultratb.py\", line 1101, in get_records\n",
      "    return _fixed_getinnerframes(etb, number_of_lines_of_context, tb_offset)\n",
      "  File \"/Users/taylorschneider/opt/anaconda3/envs/py37tf/lib/python3.7/site-packages/IPython/core/ultratb.py\", line 248, in wrapped\n",
      "    return f(*args, **kwargs)\n",
      "  File \"/Users/taylorschneider/opt/anaconda3/envs/py37tf/lib/python3.7/site-packages/IPython/core/ultratb.py\", line 281, in _fixed_getinnerframes\n",
      "    records = fix_frame_records_filenames(inspect.getinnerframes(etb, context))\n",
      "  File \"/Users/taylorschneider/opt/anaconda3/envs/py37tf/lib/python3.7/inspect.py\", line 1502, in getinnerframes\n",
      "    frameinfo = (tb.tb_frame,) + getframeinfo(tb, context)\n",
      "  File \"/Users/taylorschneider/opt/anaconda3/envs/py37tf/lib/python3.7/inspect.py\", line 1460, in getframeinfo\n",
      "    filename = getsourcefile(frame) or getfile(frame)\n",
      "  File \"/Users/taylorschneider/opt/anaconda3/envs/py37tf/lib/python3.7/inspect.py\", line 696, in getsourcefile\n",
      "    if getattr(getmodule(object, filename), '__loader__', None) is not None:\n",
      "  File \"/Users/taylorschneider/opt/anaconda3/envs/py37tf/lib/python3.7/inspect.py\", line 733, in getmodule\n",
      "    if ismodule(module) and hasattr(module, '__file__'):\n",
      "  File \"/Users/taylorschneider/opt/anaconda3/envs/py37tf/lib/python3.7/site-packages/tensorflow/__init__.py\", line 50, in __getattr__\n",
      "    module = self._load()\n",
      "  File \"/Users/taylorschneider/opt/anaconda3/envs/py37tf/lib/python3.7/site-packages/tensorflow/__init__.py\", line 44, in _load\n",
      "    module = _importlib.import_module(self.__name__)\n",
      "  File \"/Users/taylorschneider/opt/anaconda3/envs/py37tf/lib/python3.7/importlib/__init__.py\", line 127, in import_module\n",
      "    return _bootstrap._gcd_import(name[level:], package, level)\n",
      "  File \"<frozen importlib._bootstrap>\", line 1006, in _gcd_import\n",
      "  File \"<frozen importlib._bootstrap>\", line 983, in _find_and_load\n",
      "  File \"<frozen importlib._bootstrap>\", line 965, in _find_and_load_unlocked\n",
      "ModuleNotFoundError: No module named 'tensorflow_core.estimator'\n",
      "Traceback (most recent call last):\n",
      "  File \"/Users/taylorschneider/opt/anaconda3/envs/py37tf/lib/python3.7/site-packages/IPython/core/interactiveshell.py\", line 3457, in run_code\n",
      "    exec(code_obj, self.user_global_ns, self.user_ns)\n",
      "  File \"/var/folders/mx/lrbgms150gdbdt3pfhw4t3m00000gn/T/ipykernel_1380/679738915.py\", line 7, in <module>\n",
      "    history = model.fit(x_train, y_train, epochs=epochs, batch_size=100, validation_split=0.1, verbose=0) # use 10% of training dataset for validation\n",
      "  File \"/Users/taylorschneider/opt/anaconda3/envs/py37tf/lib/python3.7/site-packages/keras/engine/training.py\", line 1154, in fit\n",
      "    batch_size=batch_size)\n",
      "  File \"/Users/taylorschneider/opt/anaconda3/envs/py37tf/lib/python3.7/site-packages/keras/engine/training.py\", line 621, in _standardize_user_data\n",
      "    exception_prefix='target')\n",
      "  File \"/Users/taylorschneider/opt/anaconda3/envs/py37tf/lib/python3.7/site-packages/keras/engine/training_utils.py\", line 135, in standardize_input_data\n",
      "    'with shape ' + str(data_shape))\n",
      "ValueError: Error when checking target: expected sequential_9_input to have 4 dimensions, but got array with shape (60000, 1)\n",
      "\n",
      "During handling of the above exception, another exception occurred:\n",
      "\n",
      "Traceback (most recent call last):\n",
      "  File \"/Users/taylorschneider/opt/anaconda3/envs/py37tf/lib/python3.7/site-packages/IPython/core/interactiveshell.py\", line 2077, in showtraceback\n",
      "    stb = value._render_traceback_()\n",
      "AttributeError: 'ValueError' object has no attribute '_render_traceback_'\n",
      "\n",
      "During handling of the above exception, another exception occurred:\n",
      "\n",
      "Traceback (most recent call last):\n",
      "  File \"/Users/taylorschneider/opt/anaconda3/envs/py37tf/lib/python3.7/site-packages/IPython/core/interactiveshell.py\", line 3377, in run_ast_nodes\n",
      "    if (await self.run_code(code, result,  async_=asy)):\n",
      "  File \"/Users/taylorschneider/opt/anaconda3/envs/py37tf/lib/python3.7/site-packages/IPython/core/interactiveshell.py\", line 3474, in run_code\n",
      "    self.showtraceback(running_compiled_code=True)\n",
      "  File \"/Users/taylorschneider/opt/anaconda3/envs/py37tf/lib/python3.7/site-packages/IPython/core/interactiveshell.py\", line 2080, in showtraceback\n",
      "    value, tb, tb_offset=tb_offset)\n",
      "  File \"/Users/taylorschneider/opt/anaconda3/envs/py37tf/lib/python3.7/site-packages/IPython/core/ultratb.py\", line 1368, in structured_traceback\n",
      "    self, etype, value, tb, tb_offset, number_of_lines_of_context)\n",
      "  File \"/Users/taylorschneider/opt/anaconda3/envs/py37tf/lib/python3.7/site-packages/IPython/core/ultratb.py\", line 1268, in structured_traceback\n",
      "    self, etype, value, tb, tb_offset, number_of_lines_of_context\n",
      "  File \"/Users/taylorschneider/opt/anaconda3/envs/py37tf/lib/python3.7/site-packages/IPython/core/ultratb.py\", line 1125, in structured_traceback\n",
      "    tb_offset)\n",
      "  File \"/Users/taylorschneider/opt/anaconda3/envs/py37tf/lib/python3.7/site-packages/IPython/core/ultratb.py\", line 1082, in format_exception_as_a_whole\n",
      "    last_unique, recursion_repeat = find_recursion(orig_etype, evalue, records)\n",
      "  File \"/Users/taylorschneider/opt/anaconda3/envs/py37tf/lib/python3.7/site-packages/IPython/core/ultratb.py\", line 382, in find_recursion\n",
      "    return len(records), 0\n",
      "TypeError: object of type 'NoneType' has no len()\n",
      "\n",
      "During handling of the above exception, another exception occurred:\n",
      "\n",
      "Traceback (most recent call last):\n",
      "  File \"/Users/taylorschneider/opt/anaconda3/envs/py37tf/lib/python3.7/site-packages/IPython/core/interactiveshell.py\", line 2077, in showtraceback\n",
      "    stb = value._render_traceback_()\n",
      "AttributeError: 'TypeError' object has no attribute '_render_traceback_'\n",
      "\n",
      "During handling of the above exception, another exception occurred:\n",
      "\n",
      "Traceback (most recent call last):\n",
      "  File \"/Users/taylorschneider/opt/anaconda3/envs/py37tf/lib/python3.7/site-packages/IPython/core/interactiveshell.py\", line 2960, in _run_cell\n",
      "    return runner(coro)\n",
      "  File \"/Users/taylorschneider/opt/anaconda3/envs/py37tf/lib/python3.7/site-packages/IPython/core/async_helpers.py\", line 78, in _pseudo_sync_runner\n",
      "    coro.send(None)\n",
      "  File \"/Users/taylorschneider/opt/anaconda3/envs/py37tf/lib/python3.7/site-packages/IPython/core/interactiveshell.py\", line 3186, in run_cell_async\n",
      "    interactivity=interactivity, compiler=compiler, result=result)\n",
      "  File \"/Users/taylorschneider/opt/anaconda3/envs/py37tf/lib/python3.7/site-packages/IPython/core/interactiveshell.py\", line 3396, in run_ast_nodes\n",
      "    self.showtraceback()\n",
      "  File \"/Users/taylorschneider/opt/anaconda3/envs/py37tf/lib/python3.7/site-packages/IPython/core/interactiveshell.py\", line 2080, in showtraceback\n",
      "    value, tb, tb_offset=tb_offset)\n",
      "  File \"/Users/taylorschneider/opt/anaconda3/envs/py37tf/lib/python3.7/site-packages/IPython/core/ultratb.py\", line 1368, in structured_traceback\n",
      "    self, etype, value, tb, tb_offset, number_of_lines_of_context)\n",
      "  File \"/Users/taylorschneider/opt/anaconda3/envs/py37tf/lib/python3.7/site-packages/IPython/core/ultratb.py\", line 1268, in structured_traceback\n",
      "    self, etype, value, tb, tb_offset, number_of_lines_of_context\n",
      "  File \"/Users/taylorschneider/opt/anaconda3/envs/py37tf/lib/python3.7/site-packages/IPython/core/ultratb.py\", line 1143, in structured_traceback\n",
      "    chained_exceptions_tb_offset)\n",
      "  File \"/Users/taylorschneider/opt/anaconda3/envs/py37tf/lib/python3.7/site-packages/IPython/core/ultratb.py\", line 1082, in format_exception_as_a_whole\n",
      "    last_unique, recursion_repeat = find_recursion(orig_etype, evalue, records)\n",
      "  File \"/Users/taylorschneider/opt/anaconda3/envs/py37tf/lib/python3.7/site-packages/IPython/core/ultratb.py\", line 382, in find_recursion\n",
      "    return len(records), 0\n",
      "TypeError: object of type 'NoneType' has no len()\n",
      "\n",
      "During handling of the above exception, another exception occurred:\n",
      "\n",
      "Traceback (most recent call last):\n",
      "  File \"/Users/taylorschneider/opt/anaconda3/envs/py37tf/lib/python3.7/site-packages/IPython/core/interactiveshell.py\", line 2077, in showtraceback\n",
      "    stb = value._render_traceback_()\n",
      "AttributeError: 'TypeError' object has no attribute '_render_traceback_'\n",
      "\n",
      "During handling of the above exception, another exception occurred:\n",
      "\n",
      "Traceback (most recent call last):\n",
      "  File \"/Users/taylorschneider/opt/anaconda3/envs/py37tf/lib/python3.7/site-packages/IPython/core/ultratb.py\", line 1101, in get_records\n",
      "    return _fixed_getinnerframes(etb, number_of_lines_of_context, tb_offset)\n",
      "  File \"/Users/taylorschneider/opt/anaconda3/envs/py37tf/lib/python3.7/site-packages/IPython/core/ultratb.py\", line 248, in wrapped\n",
      "    return f(*args, **kwargs)\n",
      "  File \"/Users/taylorschneider/opt/anaconda3/envs/py37tf/lib/python3.7/site-packages/IPython/core/ultratb.py\", line 281, in _fixed_getinnerframes\n",
      "    records = fix_frame_records_filenames(inspect.getinnerframes(etb, context))\n",
      "  File \"/Users/taylorschneider/opt/anaconda3/envs/py37tf/lib/python3.7/inspect.py\", line 1502, in getinnerframes\n",
      "    frameinfo = (tb.tb_frame,) + getframeinfo(tb, context)\n",
      "  File \"/Users/taylorschneider/opt/anaconda3/envs/py37tf/lib/python3.7/inspect.py\", line 1460, in getframeinfo\n",
      "    filename = getsourcefile(frame) or getfile(frame)\n",
      "  File \"/Users/taylorschneider/opt/anaconda3/envs/py37tf/lib/python3.7/inspect.py\", line 696, in getsourcefile\n",
      "    if getattr(getmodule(object, filename), '__loader__', None) is not None:\n",
      "  File \"/Users/taylorschneider/opt/anaconda3/envs/py37tf/lib/python3.7/inspect.py\", line 733, in getmodule\n",
      "    if ismodule(module) and hasattr(module, '__file__'):\n",
      "  File \"/Users/taylorschneider/opt/anaconda3/envs/py37tf/lib/python3.7/site-packages/tensorflow/__init__.py\", line 50, in __getattr__\n",
      "    module = self._load()\n",
      "  File \"/Users/taylorschneider/opt/anaconda3/envs/py37tf/lib/python3.7/site-packages/tensorflow/__init__.py\", line 44, in _load\n",
      "    module = _importlib.import_module(self.__name__)\n",
      "  File \"/Users/taylorschneider/opt/anaconda3/envs/py37tf/lib/python3.7/importlib/__init__.py\", line 127, in import_module\n",
      "    return _bootstrap._gcd_import(name[level:], package, level)\n",
      "  File \"<frozen importlib._bootstrap>\", line 1006, in _gcd_import\n",
      "  File \"<frozen importlib._bootstrap>\", line 983, in _find_and_load\n",
      "  File \"<frozen importlib._bootstrap>\", line 965, in _find_and_load_unlocked\n",
      "ModuleNotFoundError: No module named 'tensorflow_core.estimator'\n"
     ]
    }
   ],
   "source": [
    "#train model\n",
    "tf.set_random_seed(1)\n",
    "np.random.seed(1)\n",
    "\n",
    "epochs = 20\n"
   ]
  },
  {
   "cell_type": "code",
   "execution_count": null,
   "id": "533bd54e",
   "metadata": {},
   "outputs": [
    {
     "name": "stderr",
     "output_type": "stream",
     "text": [
      "ERROR:root:Internal Python error in the inspect module.\n",
      "Below is the traceback from this internal error.\n",
      "\n",
      "ERROR:root:Internal Python error in the inspect module.\n",
      "Below is the traceback from this internal error.\n",
      "\n",
      "ERROR:root:Internal Python error in the inspect module.\n",
      "Below is the traceback from this internal error.\n",
      "\n"
     ]
    },
    {
     "name": "stdout",
     "output_type": "stream",
     "text": [
      "Traceback (most recent call last):\n",
      "  File \"/Users/taylorschneider/opt/anaconda3/envs/py37tf/lib/python3.7/site-packages/IPython/core/interactiveshell.py\", line 3457, in run_code\n",
      "    exec(code_obj, self.user_global_ns, self.user_ns)\n",
      "  File \"/var/folders/mx/lrbgms150gdbdt3pfhw4t3m00000gn/T/ipykernel_1380/4108559154.py\", line 2, in <module>\n",
      "    model.fit(x_train, y_train, validation_data=(x_test, y_test), epochs=epochs, batch_size=32, verbose=1)\n",
      "  File \"/Users/taylorschneider/opt/anaconda3/envs/py37tf/lib/python3.7/site-packages/keras/engine/training.py\", line 1154, in fit\n",
      "    batch_size=batch_size)\n",
      "  File \"/Users/taylorschneider/opt/anaconda3/envs/py37tf/lib/python3.7/site-packages/keras/engine/training.py\", line 621, in _standardize_user_data\n",
      "    exception_prefix='target')\n",
      "  File \"/Users/taylorschneider/opt/anaconda3/envs/py37tf/lib/python3.7/site-packages/keras/engine/training_utils.py\", line 135, in standardize_input_data\n",
      "    'with shape ' + str(data_shape))\n",
      "ValueError: Error when checking target: expected sequential_9_input to have 4 dimensions, but got array with shape (60000, 1)\n",
      "\n",
      "During handling of the above exception, another exception occurred:\n",
      "\n",
      "Traceback (most recent call last):\n",
      "  File \"/Users/taylorschneider/opt/anaconda3/envs/py37tf/lib/python3.7/site-packages/IPython/core/interactiveshell.py\", line 2077, in showtraceback\n",
      "    stb = value._render_traceback_()\n",
      "AttributeError: 'ValueError' object has no attribute '_render_traceback_'\n",
      "\n",
      "During handling of the above exception, another exception occurred:\n",
      "\n",
      "Traceback (most recent call last):\n",
      "  File \"/Users/taylorschneider/opt/anaconda3/envs/py37tf/lib/python3.7/site-packages/IPython/core/ultratb.py\", line 1101, in get_records\n",
      "    return _fixed_getinnerframes(etb, number_of_lines_of_context, tb_offset)\n",
      "  File \"/Users/taylorschneider/opt/anaconda3/envs/py37tf/lib/python3.7/site-packages/IPython/core/ultratb.py\", line 248, in wrapped\n",
      "    return f(*args, **kwargs)\n",
      "  File \"/Users/taylorschneider/opt/anaconda3/envs/py37tf/lib/python3.7/site-packages/IPython/core/ultratb.py\", line 281, in _fixed_getinnerframes\n",
      "    records = fix_frame_records_filenames(inspect.getinnerframes(etb, context))\n",
      "  File \"/Users/taylorschneider/opt/anaconda3/envs/py37tf/lib/python3.7/inspect.py\", line 1502, in getinnerframes\n",
      "    frameinfo = (tb.tb_frame,) + getframeinfo(tb, context)\n",
      "  File \"/Users/taylorschneider/opt/anaconda3/envs/py37tf/lib/python3.7/inspect.py\", line 1460, in getframeinfo\n",
      "    filename = getsourcefile(frame) or getfile(frame)\n",
      "  File \"/Users/taylorschneider/opt/anaconda3/envs/py37tf/lib/python3.7/inspect.py\", line 696, in getsourcefile\n",
      "    if getattr(getmodule(object, filename), '__loader__', None) is not None:\n",
      "  File \"/Users/taylorschneider/opt/anaconda3/envs/py37tf/lib/python3.7/inspect.py\", line 733, in getmodule\n",
      "    if ismodule(module) and hasattr(module, '__file__'):\n",
      "  File \"/Users/taylorschneider/opt/anaconda3/envs/py37tf/lib/python3.7/site-packages/tensorflow/__init__.py\", line 50, in __getattr__\n",
      "    module = self._load()\n",
      "  File \"/Users/taylorschneider/opt/anaconda3/envs/py37tf/lib/python3.7/site-packages/tensorflow/__init__.py\", line 44, in _load\n",
      "    module = _importlib.import_module(self.__name__)\n",
      "  File \"/Users/taylorschneider/opt/anaconda3/envs/py37tf/lib/python3.7/importlib/__init__.py\", line 127, in import_module\n",
      "    return _bootstrap._gcd_import(name[level:], package, level)\n",
      "  File \"<frozen importlib._bootstrap>\", line 1006, in _gcd_import\n",
      "  File \"<frozen importlib._bootstrap>\", line 983, in _find_and_load\n",
      "  File \"<frozen importlib._bootstrap>\", line 965, in _find_and_load_unlocked\n",
      "ModuleNotFoundError: No module named 'tensorflow_core.estimator'\n",
      "ERROR! Session/line number was not unique in database. History logging moved to new session 327\n",
      "Traceback (most recent call last):\n",
      "  File \"/Users/taylorschneider/opt/anaconda3/envs/py37tf/lib/python3.7/site-packages/IPython/core/interactiveshell.py\", line 3457, in run_code\n",
      "    exec(code_obj, self.user_global_ns, self.user_ns)\n",
      "  File \"/var/folders/mx/lrbgms150gdbdt3pfhw4t3m00000gn/T/ipykernel_1380/4108559154.py\", line 2, in <module>\n",
      "    model.fit(x_train, y_train, validation_data=(x_test, y_test), epochs=epochs, batch_size=32, verbose=1)\n",
      "  File \"/Users/taylorschneider/opt/anaconda3/envs/py37tf/lib/python3.7/site-packages/keras/engine/training.py\", line 1154, in fit\n",
      "    batch_size=batch_size)\n",
      "  File \"/Users/taylorschneider/opt/anaconda3/envs/py37tf/lib/python3.7/site-packages/keras/engine/training.py\", line 621, in _standardize_user_data\n",
      "    exception_prefix='target')\n",
      "  File \"/Users/taylorschneider/opt/anaconda3/envs/py37tf/lib/python3.7/site-packages/keras/engine/training_utils.py\", line 135, in standardize_input_data\n",
      "    'with shape ' + str(data_shape))\n",
      "ValueError: Error when checking target: expected sequential_9_input to have 4 dimensions, but got array with shape (60000, 1)\n",
      "\n",
      "During handling of the above exception, another exception occurred:\n",
      "\n",
      "Traceback (most recent call last):\n",
      "  File \"/Users/taylorschneider/opt/anaconda3/envs/py37tf/lib/python3.7/site-packages/IPython/core/interactiveshell.py\", line 2077, in showtraceback\n",
      "    stb = value._render_traceback_()\n",
      "AttributeError: 'ValueError' object has no attribute '_render_traceback_'\n",
      "\n",
      "During handling of the above exception, another exception occurred:\n",
      "\n",
      "Traceback (most recent call last):\n",
      "  File \"/Users/taylorschneider/opt/anaconda3/envs/py37tf/lib/python3.7/site-packages/IPython/core/interactiveshell.py\", line 3377, in run_ast_nodes\n",
      "    if (await self.run_code(code, result,  async_=asy)):\n",
      "  File \"/Users/taylorschneider/opt/anaconda3/envs/py37tf/lib/python3.7/site-packages/IPython/core/interactiveshell.py\", line 3474, in run_code\n",
      "    self.showtraceback(running_compiled_code=True)\n",
      "  File \"/Users/taylorschneider/opt/anaconda3/envs/py37tf/lib/python3.7/site-packages/IPython/core/interactiveshell.py\", line 2080, in showtraceback\n",
      "    value, tb, tb_offset=tb_offset)\n",
      "  File \"/Users/taylorschneider/opt/anaconda3/envs/py37tf/lib/python3.7/site-packages/IPython/core/ultratb.py\", line 1368, in structured_traceback\n",
      "    self, etype, value, tb, tb_offset, number_of_lines_of_context)\n",
      "  File \"/Users/taylorschneider/opt/anaconda3/envs/py37tf/lib/python3.7/site-packages/IPython/core/ultratb.py\", line 1268, in structured_traceback\n",
      "    self, etype, value, tb, tb_offset, number_of_lines_of_context\n",
      "  File \"/Users/taylorschneider/opt/anaconda3/envs/py37tf/lib/python3.7/site-packages/IPython/core/ultratb.py\", line 1125, in structured_traceback\n",
      "    tb_offset)\n",
      "  File \"/Users/taylorschneider/opt/anaconda3/envs/py37tf/lib/python3.7/site-packages/IPython/core/ultratb.py\", line 1082, in format_exception_as_a_whole\n",
      "    last_unique, recursion_repeat = find_recursion(orig_etype, evalue, records)\n",
      "  File \"/Users/taylorschneider/opt/anaconda3/envs/py37tf/lib/python3.7/site-packages/IPython/core/ultratb.py\", line 382, in find_recursion\n",
      "    return len(records), 0\n",
      "TypeError: object of type 'NoneType' has no len()\n",
      "\n",
      "During handling of the above exception, another exception occurred:\n",
      "\n",
      "Traceback (most recent call last):\n",
      "  File \"/Users/taylorschneider/opt/anaconda3/envs/py37tf/lib/python3.7/site-packages/IPython/core/interactiveshell.py\", line 2077, in showtraceback\n",
      "    stb = value._render_traceback_()\n",
      "AttributeError: 'TypeError' object has no attribute '_render_traceback_'\n",
      "\n",
      "During handling of the above exception, another exception occurred:\n",
      "\n",
      "Traceback (most recent call last):\n",
      "  File \"/Users/taylorschneider/opt/anaconda3/envs/py37tf/lib/python3.7/site-packages/IPython/core/ultratb.py\", line 1101, in get_records\n",
      "    return _fixed_getinnerframes(etb, number_of_lines_of_context, tb_offset)\n",
      "  File \"/Users/taylorschneider/opt/anaconda3/envs/py37tf/lib/python3.7/site-packages/IPython/core/ultratb.py\", line 248, in wrapped\n",
      "    return f(*args, **kwargs)\n",
      "  File \"/Users/taylorschneider/opt/anaconda3/envs/py37tf/lib/python3.7/site-packages/IPython/core/ultratb.py\", line 281, in _fixed_getinnerframes\n",
      "    records = fix_frame_records_filenames(inspect.getinnerframes(etb, context))\n",
      "  File \"/Users/taylorschneider/opt/anaconda3/envs/py37tf/lib/python3.7/inspect.py\", line 1502, in getinnerframes\n",
      "    frameinfo = (tb.tb_frame,) + getframeinfo(tb, context)\n",
      "  File \"/Users/taylorschneider/opt/anaconda3/envs/py37tf/lib/python3.7/inspect.py\", line 1460, in getframeinfo\n",
      "    filename = getsourcefile(frame) or getfile(frame)\n",
      "  File \"/Users/taylorschneider/opt/anaconda3/envs/py37tf/lib/python3.7/inspect.py\", line 696, in getsourcefile\n",
      "    if getattr(getmodule(object, filename), '__loader__', None) is not None:\n",
      "  File \"/Users/taylorschneider/opt/anaconda3/envs/py37tf/lib/python3.7/inspect.py\", line 733, in getmodule\n",
      "    if ismodule(module) and hasattr(module, '__file__'):\n",
      "  File \"/Users/taylorschneider/opt/anaconda3/envs/py37tf/lib/python3.7/site-packages/tensorflow/__init__.py\", line 50, in __getattr__\n",
      "    module = self._load()\n",
      "  File \"/Users/taylorschneider/opt/anaconda3/envs/py37tf/lib/python3.7/site-packages/tensorflow/__init__.py\", line 44, in _load\n",
      "    module = _importlib.import_module(self.__name__)\n",
      "  File \"/Users/taylorschneider/opt/anaconda3/envs/py37tf/lib/python3.7/importlib/__init__.py\", line 127, in import_module\n",
      "    return _bootstrap._gcd_import(name[level:], package, level)\n",
      "  File \"<frozen importlib._bootstrap>\", line 1006, in _gcd_import\n",
      "  File \"<frozen importlib._bootstrap>\", line 983, in _find_and_load\n",
      "  File \"<frozen importlib._bootstrap>\", line 965, in _find_and_load_unlocked\n",
      "ModuleNotFoundError: No module named 'tensorflow_core.estimator'\n",
      "Traceback (most recent call last):\n",
      "  File \"/Users/taylorschneider/opt/anaconda3/envs/py37tf/lib/python3.7/site-packages/IPython/core/interactiveshell.py\", line 3457, in run_code\n",
      "    exec(code_obj, self.user_global_ns, self.user_ns)\n",
      "  File \"/var/folders/mx/lrbgms150gdbdt3pfhw4t3m00000gn/T/ipykernel_1380/4108559154.py\", line 2, in <module>\n",
      "    model.fit(x_train, y_train, validation_data=(x_test, y_test), epochs=epochs, batch_size=32, verbose=1)\n",
      "  File \"/Users/taylorschneider/opt/anaconda3/envs/py37tf/lib/python3.7/site-packages/keras/engine/training.py\", line 1154, in fit\n",
      "    batch_size=batch_size)\n",
      "  File \"/Users/taylorschneider/opt/anaconda3/envs/py37tf/lib/python3.7/site-packages/keras/engine/training.py\", line 621, in _standardize_user_data\n",
      "    exception_prefix='target')\n",
      "  File \"/Users/taylorschneider/opt/anaconda3/envs/py37tf/lib/python3.7/site-packages/keras/engine/training_utils.py\", line 135, in standardize_input_data\n",
      "    'with shape ' + str(data_shape))\n",
      "ValueError: Error when checking target: expected sequential_9_input to have 4 dimensions, but got array with shape (60000, 1)\n",
      "\n",
      "During handling of the above exception, another exception occurred:\n",
      "\n",
      "Traceback (most recent call last):\n",
      "  File \"/Users/taylorschneider/opt/anaconda3/envs/py37tf/lib/python3.7/site-packages/IPython/core/interactiveshell.py\", line 2077, in showtraceback\n",
      "    stb = value._render_traceback_()\n",
      "AttributeError: 'ValueError' object has no attribute '_render_traceback_'\n",
      "\n",
      "During handling of the above exception, another exception occurred:\n",
      "\n",
      "Traceback (most recent call last):\n",
      "  File \"/Users/taylorschneider/opt/anaconda3/envs/py37tf/lib/python3.7/site-packages/IPython/core/interactiveshell.py\", line 3377, in run_ast_nodes\n",
      "    if (await self.run_code(code, result,  async_=asy)):\n",
      "  File \"/Users/taylorschneider/opt/anaconda3/envs/py37tf/lib/python3.7/site-packages/IPython/core/interactiveshell.py\", line 3474, in run_code\n",
      "    self.showtraceback(running_compiled_code=True)\n",
      "  File \"/Users/taylorschneider/opt/anaconda3/envs/py37tf/lib/python3.7/site-packages/IPython/core/interactiveshell.py\", line 2080, in showtraceback\n",
      "    value, tb, tb_offset=tb_offset)\n",
      "  File \"/Users/taylorschneider/opt/anaconda3/envs/py37tf/lib/python3.7/site-packages/IPython/core/ultratb.py\", line 1368, in structured_traceback\n",
      "    self, etype, value, tb, tb_offset, number_of_lines_of_context)\n",
      "  File \"/Users/taylorschneider/opt/anaconda3/envs/py37tf/lib/python3.7/site-packages/IPython/core/ultratb.py\", line 1268, in structured_traceback\n",
      "    self, etype, value, tb, tb_offset, number_of_lines_of_context\n",
      "  File \"/Users/taylorschneider/opt/anaconda3/envs/py37tf/lib/python3.7/site-packages/IPython/core/ultratb.py\", line 1125, in structured_traceback\n",
      "    tb_offset)\n",
      "  File \"/Users/taylorschneider/opt/anaconda3/envs/py37tf/lib/python3.7/site-packages/IPython/core/ultratb.py\", line 1082, in format_exception_as_a_whole\n",
      "    last_unique, recursion_repeat = find_recursion(orig_etype, evalue, records)\n",
      "  File \"/Users/taylorschneider/opt/anaconda3/envs/py37tf/lib/python3.7/site-packages/IPython/core/ultratb.py\", line 382, in find_recursion\n",
      "    return len(records), 0\n",
      "TypeError: object of type 'NoneType' has no len()\n",
      "\n",
      "During handling of the above exception, another exception occurred:\n",
      "\n",
      "Traceback (most recent call last):\n",
      "  File \"/Users/taylorschneider/opt/anaconda3/envs/py37tf/lib/python3.7/site-packages/IPython/core/interactiveshell.py\", line 2077, in showtraceback\n",
      "    stb = value._render_traceback_()\n",
      "AttributeError: 'TypeError' object has no attribute '_render_traceback_'\n",
      "\n",
      "During handling of the above exception, another exception occurred:\n",
      "\n",
      "Traceback (most recent call last):\n",
      "  File \"/Users/taylorschneider/opt/anaconda3/envs/py37tf/lib/python3.7/site-packages/IPython/core/interactiveshell.py\", line 2960, in _run_cell\n",
      "    return runner(coro)\n",
      "  File \"/Users/taylorschneider/opt/anaconda3/envs/py37tf/lib/python3.7/site-packages/IPython/core/async_helpers.py\", line 78, in _pseudo_sync_runner\n",
      "    coro.send(None)\n",
      "  File \"/Users/taylorschneider/opt/anaconda3/envs/py37tf/lib/python3.7/site-packages/IPython/core/interactiveshell.py\", line 3186, in run_cell_async\n",
      "    interactivity=interactivity, compiler=compiler, result=result)\n",
      "  File \"/Users/taylorschneider/opt/anaconda3/envs/py37tf/lib/python3.7/site-packages/IPython/core/interactiveshell.py\", line 3396, in run_ast_nodes\n",
      "    self.showtraceback()\n",
      "  File \"/Users/taylorschneider/opt/anaconda3/envs/py37tf/lib/python3.7/site-packages/IPython/core/interactiveshell.py\", line 2080, in showtraceback\n",
      "    value, tb, tb_offset=tb_offset)\n",
      "  File \"/Users/taylorschneider/opt/anaconda3/envs/py37tf/lib/python3.7/site-packages/IPython/core/ultratb.py\", line 1368, in structured_traceback\n",
      "    self, etype, value, tb, tb_offset, number_of_lines_of_context)\n",
      "  File \"/Users/taylorschneider/opt/anaconda3/envs/py37tf/lib/python3.7/site-packages/IPython/core/ultratb.py\", line 1268, in structured_traceback\n",
      "    self, etype, value, tb, tb_offset, number_of_lines_of_context\n",
      "  File \"/Users/taylorschneider/opt/anaconda3/envs/py37tf/lib/python3.7/site-packages/IPython/core/ultratb.py\", line 1143, in structured_traceback\n",
      "    chained_exceptions_tb_offset)\n",
      "  File \"/Users/taylorschneider/opt/anaconda3/envs/py37tf/lib/python3.7/site-packages/IPython/core/ultratb.py\", line 1082, in format_exception_as_a_whole\n",
      "    last_unique, recursion_repeat = find_recursion(orig_etype, evalue, records)\n",
      "  File \"/Users/taylorschneider/opt/anaconda3/envs/py37tf/lib/python3.7/site-packages/IPython/core/ultratb.py\", line 382, in find_recursion\n",
      "    return len(records), 0\n",
      "TypeError: object of type 'NoneType' has no len()\n",
      "\n",
      "During handling of the above exception, another exception occurred:\n",
      "\n",
      "Traceback (most recent call last):\n",
      "  File \"/Users/taylorschneider/opt/anaconda3/envs/py37tf/lib/python3.7/site-packages/IPython/core/interactiveshell.py\", line 2077, in showtraceback\n",
      "    stb = value._render_traceback_()\n",
      "AttributeError: 'TypeError' object has no attribute '_render_traceback_'\n",
      "\n",
      "During handling of the above exception, another exception occurred:\n",
      "\n",
      "Traceback (most recent call last):\n",
      "  File \"/Users/taylorschneider/opt/anaconda3/envs/py37tf/lib/python3.7/site-packages/IPython/core/ultratb.py\", line 1101, in get_records\n",
      "    return _fixed_getinnerframes(etb, number_of_lines_of_context, tb_offset)\n",
      "  File \"/Users/taylorschneider/opt/anaconda3/envs/py37tf/lib/python3.7/site-packages/IPython/core/ultratb.py\", line 248, in wrapped\n",
      "    return f(*args, **kwargs)\n",
      "  File \"/Users/taylorschneider/opt/anaconda3/envs/py37tf/lib/python3.7/site-packages/IPython/core/ultratb.py\", line 281, in _fixed_getinnerframes\n",
      "    records = fix_frame_records_filenames(inspect.getinnerframes(etb, context))\n",
      "  File \"/Users/taylorschneider/opt/anaconda3/envs/py37tf/lib/python3.7/inspect.py\", line 1502, in getinnerframes\n",
      "    frameinfo = (tb.tb_frame,) + getframeinfo(tb, context)\n",
      "  File \"/Users/taylorschneider/opt/anaconda3/envs/py37tf/lib/python3.7/inspect.py\", line 1460, in getframeinfo\n",
      "    filename = getsourcefile(frame) or getfile(frame)\n",
      "  File \"/Users/taylorschneider/opt/anaconda3/envs/py37tf/lib/python3.7/inspect.py\", line 696, in getsourcefile\n",
      "    if getattr(getmodule(object, filename), '__loader__', None) is not None:\n",
      "  File \"/Users/taylorschneider/opt/anaconda3/envs/py37tf/lib/python3.7/inspect.py\", line 733, in getmodule\n",
      "    if ismodule(module) and hasattr(module, '__file__'):\n",
      "  File \"/Users/taylorschneider/opt/anaconda3/envs/py37tf/lib/python3.7/site-packages/tensorflow/__init__.py\", line 50, in __getattr__\n",
      "    module = self._load()\n",
      "  File \"/Users/taylorschneider/opt/anaconda3/envs/py37tf/lib/python3.7/site-packages/tensorflow/__init__.py\", line 44, in _load\n",
      "    module = _importlib.import_module(self.__name__)\n",
      "  File \"/Users/taylorschneider/opt/anaconda3/envs/py37tf/lib/python3.7/importlib/__init__.py\", line 127, in import_module\n",
      "    return _bootstrap._gcd_import(name[level:], package, level)\n",
      "  File \"<frozen importlib._bootstrap>\", line 1006, in _gcd_import\n",
      "  File \"<frozen importlib._bootstrap>\", line 983, in _find_and_load\n",
      "  File \"<frozen importlib._bootstrap>\", line 965, in _find_and_load_unlocked\n",
      "ModuleNotFoundError: No module named 'tensorflow_core.estimator'\n"
     ]
    }
   ],
   "source": [
    "# Fit the model\n",
    "model.fit(x_train, y_train, validation_data=(x_test, y_test), epochs=epochs, batch_size=32, verbose=1)"
   ]
  },
  {
   "cell_type": "code",
   "execution_count": null,
   "id": "29f40961",
   "metadata": {},
   "outputs": [
    {
     "name": "stderr",
     "output_type": "stream",
     "text": [
      "ERROR:root:Internal Python error in the inspect module.\n",
      "Below is the traceback from this internal error.\n",
      "\n",
      "ERROR:root:Internal Python error in the inspect module.\n",
      "Below is the traceback from this internal error.\n",
      "\n",
      "ERROR:root:Internal Python error in the inspect module.\n",
      "Below is the traceback from this internal error.\n",
      "\n"
     ]
    },
    {
     "name": "stdout",
     "output_type": "stream",
     "text": [
      "ERROR! Session/line number was not unique in database. History logging moved to new session 324\n",
      "Traceback (most recent call last):\n",
      "  File \"/Users/taylorschneider/opt/anaconda3/envs/py37tf/lib/python3.7/site-packages/IPython/core/interactiveshell.py\", line 3457, in run_code\n",
      "    exec(code_obj, self.user_global_ns, self.user_ns)\n",
      "  File \"/var/folders/mx/lrbgms150gdbdt3pfhw4t3m00000gn/T/ipykernel_1380/845310997.py\", line 2, in <module>\n",
      "    scores = model.evaluate(x_test, y_test, verbose=0)\n",
      "  File \"/Users/taylorschneider/opt/anaconda3/envs/py37tf/lib/python3.7/site-packages/keras/engine/training.py\", line 1349, in evaluate\n",
      "    batch_size=batch_size)\n",
      "  File \"/Users/taylorschneider/opt/anaconda3/envs/py37tf/lib/python3.7/site-packages/keras/engine/training.py\", line 621, in _standardize_user_data\n",
      "    exception_prefix='target')\n",
      "  File \"/Users/taylorschneider/opt/anaconda3/envs/py37tf/lib/python3.7/site-packages/keras/engine/training_utils.py\", line 135, in standardize_input_data\n",
      "    'with shape ' + str(data_shape))\n",
      "ValueError: Error when checking target: expected sequential_9_input to have 4 dimensions, but got array with shape (10000, 1)\n",
      "\n",
      "During handling of the above exception, another exception occurred:\n",
      "\n",
      "Traceback (most recent call last):\n",
      "  File \"/Users/taylorschneider/opt/anaconda3/envs/py37tf/lib/python3.7/site-packages/IPython/core/interactiveshell.py\", line 2077, in showtraceback\n",
      "    stb = value._render_traceback_()\n",
      "AttributeError: 'ValueError' object has no attribute '_render_traceback_'\n",
      "\n",
      "During handling of the above exception, another exception occurred:\n",
      "\n",
      "Traceback (most recent call last):\n",
      "  File \"/Users/taylorschneider/opt/anaconda3/envs/py37tf/lib/python3.7/site-packages/IPython/core/ultratb.py\", line 1101, in get_records\n",
      "    return _fixed_getinnerframes(etb, number_of_lines_of_context, tb_offset)\n",
      "  File \"/Users/taylorschneider/opt/anaconda3/envs/py37tf/lib/python3.7/site-packages/IPython/core/ultratb.py\", line 248, in wrapped\n",
      "    return f(*args, **kwargs)\n",
      "  File \"/Users/taylorschneider/opt/anaconda3/envs/py37tf/lib/python3.7/site-packages/IPython/core/ultratb.py\", line 281, in _fixed_getinnerframes\n",
      "    records = fix_frame_records_filenames(inspect.getinnerframes(etb, context))\n",
      "  File \"/Users/taylorschneider/opt/anaconda3/envs/py37tf/lib/python3.7/inspect.py\", line 1502, in getinnerframes\n",
      "    frameinfo = (tb.tb_frame,) + getframeinfo(tb, context)\n",
      "  File \"/Users/taylorschneider/opt/anaconda3/envs/py37tf/lib/python3.7/inspect.py\", line 1460, in getframeinfo\n",
      "    filename = getsourcefile(frame) or getfile(frame)\n",
      "  File \"/Users/taylorschneider/opt/anaconda3/envs/py37tf/lib/python3.7/inspect.py\", line 696, in getsourcefile\n",
      "    if getattr(getmodule(object, filename), '__loader__', None) is not None:\n",
      "  File \"/Users/taylorschneider/opt/anaconda3/envs/py37tf/lib/python3.7/inspect.py\", line 733, in getmodule\n",
      "    if ismodule(module) and hasattr(module, '__file__'):\n",
      "  File \"/Users/taylorschneider/opt/anaconda3/envs/py37tf/lib/python3.7/site-packages/tensorflow/__init__.py\", line 50, in __getattr__\n",
      "    module = self._load()\n",
      "  File \"/Users/taylorschneider/opt/anaconda3/envs/py37tf/lib/python3.7/site-packages/tensorflow/__init__.py\", line 44, in _load\n",
      "    module = _importlib.import_module(self.__name__)\n",
      "  File \"/Users/taylorschneider/opt/anaconda3/envs/py37tf/lib/python3.7/importlib/__init__.py\", line 127, in import_module\n",
      "    return _bootstrap._gcd_import(name[level:], package, level)\n",
      "  File \"<frozen importlib._bootstrap>\", line 1006, in _gcd_import\n",
      "  File \"<frozen importlib._bootstrap>\", line 983, in _find_and_load\n",
      "  File \"<frozen importlib._bootstrap>\", line 965, in _find_and_load_unlocked\n",
      "ModuleNotFoundError: No module named 'tensorflow_core.estimator'\n",
      "Traceback (most recent call last):\n",
      "  File \"/Users/taylorschneider/opt/anaconda3/envs/py37tf/lib/python3.7/site-packages/IPython/core/interactiveshell.py\", line 3457, in run_code\n",
      "    exec(code_obj, self.user_global_ns, self.user_ns)\n",
      "  File \"/var/folders/mx/lrbgms150gdbdt3pfhw4t3m00000gn/T/ipykernel_1380/845310997.py\", line 2, in <module>\n",
      "    scores = model.evaluate(x_test, y_test, verbose=0)\n",
      "  File \"/Users/taylorschneider/opt/anaconda3/envs/py37tf/lib/python3.7/site-packages/keras/engine/training.py\", line 1349, in evaluate\n",
      "    batch_size=batch_size)\n",
      "  File \"/Users/taylorschneider/opt/anaconda3/envs/py37tf/lib/python3.7/site-packages/keras/engine/training.py\", line 621, in _standardize_user_data\n",
      "    exception_prefix='target')\n",
      "  File \"/Users/taylorschneider/opt/anaconda3/envs/py37tf/lib/python3.7/site-packages/keras/engine/training_utils.py\", line 135, in standardize_input_data\n",
      "    'with shape ' + str(data_shape))\n",
      "ValueError: Error when checking target: expected sequential_9_input to have 4 dimensions, but got array with shape (10000, 1)\n",
      "\n",
      "During handling of the above exception, another exception occurred:\n",
      "\n",
      "Traceback (most recent call last):\n",
      "  File \"/Users/taylorschneider/opt/anaconda3/envs/py37tf/lib/python3.7/site-packages/IPython/core/interactiveshell.py\", line 2077, in showtraceback\n",
      "    stb = value._render_traceback_()\n",
      "AttributeError: 'ValueError' object has no attribute '_render_traceback_'\n",
      "\n",
      "During handling of the above exception, another exception occurred:\n",
      "\n",
      "Traceback (most recent call last):\n",
      "  File \"/Users/taylorschneider/opt/anaconda3/envs/py37tf/lib/python3.7/site-packages/IPython/core/interactiveshell.py\", line 3377, in run_ast_nodes\n",
      "    if (await self.run_code(code, result,  async_=asy)):\n",
      "  File \"/Users/taylorschneider/opt/anaconda3/envs/py37tf/lib/python3.7/site-packages/IPython/core/interactiveshell.py\", line 3474, in run_code\n",
      "    self.showtraceback(running_compiled_code=True)\n",
      "  File \"/Users/taylorschneider/opt/anaconda3/envs/py37tf/lib/python3.7/site-packages/IPython/core/interactiveshell.py\", line 2080, in showtraceback\n",
      "    value, tb, tb_offset=tb_offset)\n",
      "  File \"/Users/taylorschneider/opt/anaconda3/envs/py37tf/lib/python3.7/site-packages/IPython/core/ultratb.py\", line 1368, in structured_traceback\n",
      "    self, etype, value, tb, tb_offset, number_of_lines_of_context)\n",
      "  File \"/Users/taylorschneider/opt/anaconda3/envs/py37tf/lib/python3.7/site-packages/IPython/core/ultratb.py\", line 1268, in structured_traceback\n",
      "    self, etype, value, tb, tb_offset, number_of_lines_of_context\n",
      "  File \"/Users/taylorschneider/opt/anaconda3/envs/py37tf/lib/python3.7/site-packages/IPython/core/ultratb.py\", line 1125, in structured_traceback\n",
      "    tb_offset)\n",
      "  File \"/Users/taylorschneider/opt/anaconda3/envs/py37tf/lib/python3.7/site-packages/IPython/core/ultratb.py\", line 1082, in format_exception_as_a_whole\n",
      "    last_unique, recursion_repeat = find_recursion(orig_etype, evalue, records)\n",
      "  File \"/Users/taylorschneider/opt/anaconda3/envs/py37tf/lib/python3.7/site-packages/IPython/core/ultratb.py\", line 382, in find_recursion\n",
      "    return len(records), 0\n",
      "TypeError: object of type 'NoneType' has no len()\n",
      "\n",
      "During handling of the above exception, another exception occurred:\n",
      "\n",
      "Traceback (most recent call last):\n",
      "  File \"/Users/taylorschneider/opt/anaconda3/envs/py37tf/lib/python3.7/site-packages/IPython/core/interactiveshell.py\", line 2077, in showtraceback\n",
      "    stb = value._render_traceback_()\n",
      "AttributeError: 'TypeError' object has no attribute '_render_traceback_'\n",
      "\n",
      "During handling of the above exception, another exception occurred:\n",
      "\n",
      "Traceback (most recent call last):\n",
      "  File \"/Users/taylorschneider/opt/anaconda3/envs/py37tf/lib/python3.7/site-packages/IPython/core/ultratb.py\", line 1101, in get_records\n",
      "    return _fixed_getinnerframes(etb, number_of_lines_of_context, tb_offset)\n",
      "  File \"/Users/taylorschneider/opt/anaconda3/envs/py37tf/lib/python3.7/site-packages/IPython/core/ultratb.py\", line 248, in wrapped\n",
      "    return f(*args, **kwargs)\n",
      "  File \"/Users/taylorschneider/opt/anaconda3/envs/py37tf/lib/python3.7/site-packages/IPython/core/ultratb.py\", line 281, in _fixed_getinnerframes\n",
      "    records = fix_frame_records_filenames(inspect.getinnerframes(etb, context))\n",
      "  File \"/Users/taylorschneider/opt/anaconda3/envs/py37tf/lib/python3.7/inspect.py\", line 1502, in getinnerframes\n",
      "    frameinfo = (tb.tb_frame,) + getframeinfo(tb, context)\n",
      "  File \"/Users/taylorschneider/opt/anaconda3/envs/py37tf/lib/python3.7/inspect.py\", line 1460, in getframeinfo\n",
      "    filename = getsourcefile(frame) or getfile(frame)\n",
      "  File \"/Users/taylorschneider/opt/anaconda3/envs/py37tf/lib/python3.7/inspect.py\", line 696, in getsourcefile\n",
      "    if getattr(getmodule(object, filename), '__loader__', None) is not None:\n",
      "  File \"/Users/taylorschneider/opt/anaconda3/envs/py37tf/lib/python3.7/inspect.py\", line 733, in getmodule\n",
      "    if ismodule(module) and hasattr(module, '__file__'):\n",
      "  File \"/Users/taylorschneider/opt/anaconda3/envs/py37tf/lib/python3.7/site-packages/tensorflow/__init__.py\", line 50, in __getattr__\n",
      "    module = self._load()\n",
      "  File \"/Users/taylorschneider/opt/anaconda3/envs/py37tf/lib/python3.7/site-packages/tensorflow/__init__.py\", line 44, in _load\n",
      "    module = _importlib.import_module(self.__name__)\n",
      "  File \"/Users/taylorschneider/opt/anaconda3/envs/py37tf/lib/python3.7/importlib/__init__.py\", line 127, in import_module\n",
      "    return _bootstrap._gcd_import(name[level:], package, level)\n",
      "  File \"<frozen importlib._bootstrap>\", line 1006, in _gcd_import\n",
      "  File \"<frozen importlib._bootstrap>\", line 983, in _find_and_load\n",
      "  File \"<frozen importlib._bootstrap>\", line 965, in _find_and_load_unlocked\n",
      "ModuleNotFoundError: No module named 'tensorflow_core.estimator'\n",
      "Traceback (most recent call last):\n",
      "  File \"/Users/taylorschneider/opt/anaconda3/envs/py37tf/lib/python3.7/site-packages/IPython/core/interactiveshell.py\", line 3457, in run_code\n",
      "    exec(code_obj, self.user_global_ns, self.user_ns)\n",
      "  File \"/var/folders/mx/lrbgms150gdbdt3pfhw4t3m00000gn/T/ipykernel_1380/845310997.py\", line 2, in <module>\n",
      "    scores = model.evaluate(x_test, y_test, verbose=0)\n",
      "  File \"/Users/taylorschneider/opt/anaconda3/envs/py37tf/lib/python3.7/site-packages/keras/engine/training.py\", line 1349, in evaluate\n",
      "    batch_size=batch_size)\n",
      "  File \"/Users/taylorschneider/opt/anaconda3/envs/py37tf/lib/python3.7/site-packages/keras/engine/training.py\", line 621, in _standardize_user_data\n",
      "    exception_prefix='target')\n",
      "  File \"/Users/taylorschneider/opt/anaconda3/envs/py37tf/lib/python3.7/site-packages/keras/engine/training_utils.py\", line 135, in standardize_input_data\n",
      "    'with shape ' + str(data_shape))\n",
      "ValueError: Error when checking target: expected sequential_9_input to have 4 dimensions, but got array with shape (10000, 1)\n",
      "\n",
      "During handling of the above exception, another exception occurred:\n",
      "\n",
      "Traceback (most recent call last):\n",
      "  File \"/Users/taylorschneider/opt/anaconda3/envs/py37tf/lib/python3.7/site-packages/IPython/core/interactiveshell.py\", line 2077, in showtraceback\n",
      "    stb = value._render_traceback_()\n",
      "AttributeError: 'ValueError' object has no attribute '_render_traceback_'\n",
      "\n",
      "During handling of the above exception, another exception occurred:\n",
      "\n",
      "Traceback (most recent call last):\n",
      "  File \"/Users/taylorschneider/opt/anaconda3/envs/py37tf/lib/python3.7/site-packages/IPython/core/interactiveshell.py\", line 3377, in run_ast_nodes\n",
      "    if (await self.run_code(code, result,  async_=asy)):\n",
      "  File \"/Users/taylorschneider/opt/anaconda3/envs/py37tf/lib/python3.7/site-packages/IPython/core/interactiveshell.py\", line 3474, in run_code\n",
      "    self.showtraceback(running_compiled_code=True)\n",
      "  File \"/Users/taylorschneider/opt/anaconda3/envs/py37tf/lib/python3.7/site-packages/IPython/core/interactiveshell.py\", line 2080, in showtraceback\n",
      "    value, tb, tb_offset=tb_offset)\n",
      "  File \"/Users/taylorschneider/opt/anaconda3/envs/py37tf/lib/python3.7/site-packages/IPython/core/ultratb.py\", line 1368, in structured_traceback\n",
      "    self, etype, value, tb, tb_offset, number_of_lines_of_context)\n",
      "  File \"/Users/taylorschneider/opt/anaconda3/envs/py37tf/lib/python3.7/site-packages/IPython/core/ultratb.py\", line 1268, in structured_traceback\n",
      "    self, etype, value, tb, tb_offset, number_of_lines_of_context\n",
      "  File \"/Users/taylorschneider/opt/anaconda3/envs/py37tf/lib/python3.7/site-packages/IPython/core/ultratb.py\", line 1125, in structured_traceback\n",
      "    tb_offset)\n",
      "  File \"/Users/taylorschneider/opt/anaconda3/envs/py37tf/lib/python3.7/site-packages/IPython/core/ultratb.py\", line 1082, in format_exception_as_a_whole\n",
      "    last_unique, recursion_repeat = find_recursion(orig_etype, evalue, records)\n",
      "  File \"/Users/taylorschneider/opt/anaconda3/envs/py37tf/lib/python3.7/site-packages/IPython/core/ultratb.py\", line 382, in find_recursion\n",
      "    return len(records), 0\n",
      "TypeError: object of type 'NoneType' has no len()\n",
      "\n",
      "During handling of the above exception, another exception occurred:\n",
      "\n",
      "Traceback (most recent call last):\n",
      "  File \"/Users/taylorschneider/opt/anaconda3/envs/py37tf/lib/python3.7/site-packages/IPython/core/interactiveshell.py\", line 2077, in showtraceback\n",
      "    stb = value._render_traceback_()\n",
      "AttributeError: 'TypeError' object has no attribute '_render_traceback_'\n",
      "\n",
      "During handling of the above exception, another exception occurred:\n",
      "\n",
      "Traceback (most recent call last):\n",
      "  File \"/Users/taylorschneider/opt/anaconda3/envs/py37tf/lib/python3.7/site-packages/IPython/core/interactiveshell.py\", line 2960, in _run_cell\n",
      "    return runner(coro)\n",
      "  File \"/Users/taylorschneider/opt/anaconda3/envs/py37tf/lib/python3.7/site-packages/IPython/core/async_helpers.py\", line 78, in _pseudo_sync_runner\n",
      "    coro.send(None)\n",
      "  File \"/Users/taylorschneider/opt/anaconda3/envs/py37tf/lib/python3.7/site-packages/IPython/core/interactiveshell.py\", line 3186, in run_cell_async\n",
      "    interactivity=interactivity, compiler=compiler, result=result)\n",
      "  File \"/Users/taylorschneider/opt/anaconda3/envs/py37tf/lib/python3.7/site-packages/IPython/core/interactiveshell.py\", line 3396, in run_ast_nodes\n",
      "    self.showtraceback()\n",
      "  File \"/Users/taylorschneider/opt/anaconda3/envs/py37tf/lib/python3.7/site-packages/IPython/core/interactiveshell.py\", line 2080, in showtraceback\n",
      "    value, tb, tb_offset=tb_offset)\n",
      "  File \"/Users/taylorschneider/opt/anaconda3/envs/py37tf/lib/python3.7/site-packages/IPython/core/ultratb.py\", line 1368, in structured_traceback\n",
      "    self, etype, value, tb, tb_offset, number_of_lines_of_context)\n",
      "  File \"/Users/taylorschneider/opt/anaconda3/envs/py37tf/lib/python3.7/site-packages/IPython/core/ultratb.py\", line 1268, in structured_traceback\n",
      "    self, etype, value, tb, tb_offset, number_of_lines_of_context\n",
      "  File \"/Users/taylorschneider/opt/anaconda3/envs/py37tf/lib/python3.7/site-packages/IPython/core/ultratb.py\", line 1143, in structured_traceback\n",
      "    chained_exceptions_tb_offset)\n",
      "  File \"/Users/taylorschneider/opt/anaconda3/envs/py37tf/lib/python3.7/site-packages/IPython/core/ultratb.py\", line 1082, in format_exception_as_a_whole\n",
      "    last_unique, recursion_repeat = find_recursion(orig_etype, evalue, records)\n",
      "  File \"/Users/taylorschneider/opt/anaconda3/envs/py37tf/lib/python3.7/site-packages/IPython/core/ultratb.py\", line 382, in find_recursion\n",
      "    return len(records), 0\n",
      "TypeError: object of type 'NoneType' has no len()\n",
      "\n",
      "During handling of the above exception, another exception occurred:\n",
      "\n",
      "Traceback (most recent call last):\n",
      "  File \"/Users/taylorschneider/opt/anaconda3/envs/py37tf/lib/python3.7/site-packages/IPython/core/interactiveshell.py\", line 2077, in showtraceback\n",
      "    stb = value._render_traceback_()\n",
      "AttributeError: 'TypeError' object has no attribute '_render_traceback_'\n",
      "\n",
      "During handling of the above exception, another exception occurred:\n",
      "\n",
      "Traceback (most recent call last):\n",
      "  File \"/Users/taylorschneider/opt/anaconda3/envs/py37tf/lib/python3.7/site-packages/IPython/core/ultratb.py\", line 1101, in get_records\n",
      "    return _fixed_getinnerframes(etb, number_of_lines_of_context, tb_offset)\n",
      "  File \"/Users/taylorschneider/opt/anaconda3/envs/py37tf/lib/python3.7/site-packages/IPython/core/ultratb.py\", line 248, in wrapped\n",
      "    return f(*args, **kwargs)\n",
      "  File \"/Users/taylorschneider/opt/anaconda3/envs/py37tf/lib/python3.7/site-packages/IPython/core/ultratb.py\", line 281, in _fixed_getinnerframes\n",
      "    records = fix_frame_records_filenames(inspect.getinnerframes(etb, context))\n",
      "  File \"/Users/taylorschneider/opt/anaconda3/envs/py37tf/lib/python3.7/inspect.py\", line 1502, in getinnerframes\n",
      "    frameinfo = (tb.tb_frame,) + getframeinfo(tb, context)\n",
      "  File \"/Users/taylorschneider/opt/anaconda3/envs/py37tf/lib/python3.7/inspect.py\", line 1460, in getframeinfo\n",
      "    filename = getsourcefile(frame) or getfile(frame)\n",
      "  File \"/Users/taylorschneider/opt/anaconda3/envs/py37tf/lib/python3.7/inspect.py\", line 696, in getsourcefile\n",
      "    if getattr(getmodule(object, filename), '__loader__', None) is not None:\n",
      "  File \"/Users/taylorschneider/opt/anaconda3/envs/py37tf/lib/python3.7/inspect.py\", line 733, in getmodule\n",
      "    if ismodule(module) and hasattr(module, '__file__'):\n",
      "  File \"/Users/taylorschneider/opt/anaconda3/envs/py37tf/lib/python3.7/site-packages/tensorflow/__init__.py\", line 50, in __getattr__\n",
      "    module = self._load()\n",
      "  File \"/Users/taylorschneider/opt/anaconda3/envs/py37tf/lib/python3.7/site-packages/tensorflow/__init__.py\", line 44, in _load\n",
      "    module = _importlib.import_module(self.__name__)\n",
      "  File \"/Users/taylorschneider/opt/anaconda3/envs/py37tf/lib/python3.7/importlib/__init__.py\", line 127, in import_module\n",
      "    return _bootstrap._gcd_import(name[level:], package, level)\n",
      "  File \"<frozen importlib._bootstrap>\", line 1006, in _gcd_import\n",
      "  File \"<frozen importlib._bootstrap>\", line 983, in _find_and_load\n",
      "  File \"<frozen importlib._bootstrap>\", line 965, in _find_and_load_unlocked\n",
      "ModuleNotFoundError: No module named 'tensorflow_core.estimator'\n"
     ]
    }
   ],
   "source": [
    "# Evaluate Model\n",
    "scores = model.evaluate(x_test, y_test, verbose=0)\n",
    "print(\"Accuracy: %.2f%%\" % (scores[1]*100))"
   ]
  }
 ],
 "metadata": {
  "kernelspec": {
   "display_name": "Python 3 (ipykernel)",
   "language": "python",
   "name": "python3"
  },
  "language_info": {
   "codemirror_mode": {
    "name": "ipython",
    "version": 3
   },
   "file_extension": ".py",
   "mimetype": "text/x-python",
   "name": "python",
   "nbconvert_exporter": "python",
   "pygments_lexer": "ipython3",
   "version": "3.7.13"
  }
 },
 "nbformat": 4,
 "nbformat_minor": 5
}
